Workbook

Sheet Daftar Isi
A1: Daftar Isi Portofolio Mata Kuliah
A3: No. | B3: Nama Sheet | C3: Keterangan
A4: 1 | B4: Master Data | C4: Isi identitas mata kuliah
A5: 2 | B5: Matriks Asesmen | C5: Isi bobot tiap bentuk penilaian sesuai dengan tiap CPMK
A6: 3 | B6: 0. Daftar Kelengkapan Portofolio | C6: Beri centang pada kolom yang telah selesai dikerjakan
A7: 4 | B7: 1. Portofolio MK | C7: Tulis deskripsi tentang proses pembelajaran pada MK sesuai dengan kolom yang disediakan.
A8: 5 | B8: 2. RPS | C8: Masukkan tautan RPS
A9: 6 | B9: 3. Kontrak Kuliah | C9: Masukkan tautan Kontrak Kuliah
A10: 7 | B10: 4. Presensi SIPA | C10: Masukkan tautan Presensi SIPA
A11: 8 | B11: 5. Rekap Presensi | C11: Isi dengan presensi mahasiswa
A12: 9 | B12: 6. Soal Ujian | C12: Masukkan tautan Soal Ujian
A13: 10 | B13: 7. Rekap Nilai | C13: Isi dengan nilai mahasiswa
A14: 11 | B14: 8. CPMK A | C14: Terisi otomatis jika pengisian data sheet-sheet sebelumnya sudah benar
... A19: 16 | B19: 13. Laporan OBE | C19: Terisi otomatis jika pengisian data sheet-sheet sebelumnya sudah benar

Sheet Master Data
B1: MASTER DATA
A3: I | B3: Tahun Akademik
A4: II | B4: Nama MK
A5: III | B5: Kode MK
A6: IV | B6: SKS
A7: V | B7: Semester
A8: VI | B8: Kelas
A9: VII | B9: Jumlah Dosen Pengampu
A10: VIII | B10: Nama Dosen Pengampu 1
A11: IX | B11: Nama Dosen Pengampu 2
A12: X | B12: Koordinator Program Studi
A13: XI | B13: Jumlah Mahasiswa
A14: XII | B14: Jumlah Pertemuan
A15: XIII | B15: Fakultas | C15: Fakultas …
A16: XIV | B16: Jurusan | C16: Jurusan …
A17: XV | B17: Program Studi | C17: Program Studi …
B19: DAFTAR PESERTA KULIAH
A20: No | B20: NIM | C20: NAMA
A21: 1
A22: 2
A23: 3
A24: 4
A25: 5
A26: 6
A27: 7
A28: 8
A29: 9
A30: 10
A31: 11
A32: 12
... A75: 55

Sheet Matriks Asesmen
A1: MATRIK PENILAIAN TERHADAP CPMK
A2: ASSESMENT | B2: CPMK A | C2: CPMK B | D2: CPMK C | E2: CPMK D | F2: CPMK E | G2: TOTAL
A3: Tentukan Proporsi Yang Diinginkan | G3: =SUM(B3:F3) -> 0
A4: UTS | B4: 0.1 | C4: 0.15 | G4: =SUM(B4:F4) -> 0.25
A5: UAS | B5: 0.1 | C5: 0.1 | D5: 0.1 | G5: =SUM(B5:F5) -> 0.3
A6: Keaktifan | B6: 0.05 | C6: 0.05 | D6: 0.05 | G6: =SUM(B6:F6) -> 0.15
A7: Tugas 1 | B7: 0.05 | G7: =SUM(B7:F7) -> 0.05
A8: Tugas 2 | C8: 0.05 | G8: =SUM(B8:F8) -> 0.05
A9: Tugas 3 | C9: 0.05 | D9: 0.05 | G9: =SUM(B9:F9) -> 0.1
A10: Tugas 4 | C10: 0.05 | D10: 0.05 | G10: =SUM(B10:F10) -> 0.1
A11: (bentuk penilaian lainnya) | G11: =SUM(B11:F11) -> 0
A12: (bentuk penilaian lainnya) | G12: =SUM(B12:F12) -> 0
A13: (bentuk penilaian lainnya) | G13: =SUM(B13:F13) -> 0
A14: PROPORSI | B14: =SUM(B4:B13) -> 0.3 | C14: =SUM(C4:C13) -> 0.45 | D14: =SUM(D4:D13) -> 0.25 | E14: =SUM(E4:E13) -> 0 | F14: =SUM(F4:F13) -> 0 | G14: =SUM(G4:G13) -> 1

Sheet 0.Daftar Kelengkapan Portofolio
C1: UNIVERSITAS MARITIM RAJA ALI HAJI
C2: ='Master Data'!C15 -> Fakultas …
C3: ='Master Data'!C16 -> Jurusan …
C4: ='Master Data'!C17 -> Program Studi …
A6: DAFTAR KELENGKAPAN PORTOFOLIO MATA KULIAH
A7: ="Tahun Akademik: " &'Master Data'!C3 -> Tahun Akademik: | D7: ="Semester: "&ROMAN('Master Data'!C7)&" / "&IF(MOD('Master Data'!C7,2),"Ganjil","Genap") -> #VALUE!
A8: ="Nama MK: "&'Master Data'!C4 -> Nama MK: | D8: ="Kode: "&'Master Data'!C5 -> Kode:
A9: ="Kelas: "&'Master Data'!C8 -> Kelas: | D9: ="SKS : "&'Master Data'!C6 -> SKS :
A10: Dosen Pengampu:
A11: 1) | B11: ='Master Data'!C10
A12: =IF('Master Data'!C9>1,"2)","") | B12: =IF('Master Data'!C9>1,'Master Data'!C11,"")
A13: No. | B13: Daftar Kelengkapan Portofolio MK | D13: Status Kelengkapan
D14: Ada | F14: Tidak Ada
A15: 1 | B15: Portofolio MK
A16: 2 | B16: Analisis Pembelajaran
A17: 3 | B17: Rencana Pembelajaran Semester (RPS)
A18: 4 | B18: Basis Evaluasi Penilaian
A19: 5 | B19: Lembar Tugas Mahasiswa
A20: 6 | B20: Kontrak Perkuliahan
A21: 7 | B21: Jurnal Perkuliahan (SIPA)
A22: 8 | B22: Rekapitulasi Presensi
A23: 9 | B23: Soal Asesmen:
B24: a) | C24: UTS*
B25: b) | C25: UAS*
B26: c) | C26: Proyek/Case Method*
A27: 10 | B27: Rekapitulasi Nilai Akhir
A28: 11 | B28: Rekapitulasi Hasil Pencapaian Tiap CPMK
A29: 12 | B29: OBE: Laporan Pencapaian Keseluruhan Capaian Pembelajaran Mata Kuliah (CPMK)
A30: Catatan: 1. *) Coret yang tidak perlu 2. Berilah tanda pada status kelengkapan dengan ✓ pada kolom yang tersedia 3. Berikan tanda tangan untuk dosen pengampu MK yang bersangkutan
A31: Dosen Pengampu I, | D31: =IF('Master Data'!C9>1,"Dosen Pengampu II,","")
A36: =B11 | D36: =B12
D38: ='Master Data'!B12 -> Koordinator Program Studi
D42: ='Master Data'!C12

Sheet 1.Portofolio MK
B1: UNIVERSITAS MARITIM RAJA ALI HAJI
B2: ='Master Data'!C15 -> Fakultas …
B3: ='Master Data'!C16 -> Jurusan …
B4: ='Master Data'!C17 -> Program Studi …
A6: PORTOFOLIO MATA KULIAH
A7: ="Tahun Akademik: " &'Master Data'!C3 -> Tahun Akademik: | D7: ="Semester: "&ROMAN('Master Data'!C7)&" / "&IF(MOD('Master Data'!C7,2),"Ganjil","Genap") -> #VALUE!
A8: ="Nama MK: "&'Master Data'!C4 -> Nama MK: | D8: ="Kode: "&'Master Data'!C5 -> Kode:
A9: ="Kelas: "&'Master Data'!C8 -> Kelas: | D9: ="SKS : "&'Master Data'!C6 -> SKS :
A10: Dosen Pengampu:
A11: 1) | B11: ='Master Data'!C10
A12: =IF('Master Data'!C9>1,"2)","") | B12: =IF('Master Data'!C9>1,'Master Data'!C11,"")
A13: 1 | B13: Pendahuluan (Ceritakan penjelasan yang diperlukan tentang mata kuliah ini)
A15: 2 | B15: Tujuan (Jelaskan tujuan perkuliahan umum maupun khusus)
A17: 3 | B17: Metode Pembelajaran ( Jelaskan strategi yang digunakan untuk mencapai tujuan perkuliahan - CPMK)
A19: 4 | B19: Isi Perkuliahan (jelaskan kesuaiannya dengan kurikulum yang berlaku)
A21: 5 | B21: Peserta Kuliah (berikan gambaran tentang peserta kuliah)
A23: 6 | B23: Persentase Kehadiran (% kehadiran dosen ; % kehadiran mahasiswa)
A25: 7 | B25: Sistem Evaluasi (jelaskan tentang PR, Kuis, tugas kelompok, praktikum , dll)
A27: 8 | B27: Hasil Capaian Pembelajaran (jelaskan tentang capaian atas tujuan yang telah ditetapkan, masukkan pula ketercapaian pembelajaran yang dapat dijelaskan)
B28: ='Matriks Asesmen'!B2&" :" -> CPMK A :
B29: SANGAT BAIK | C29: BAIK | D29: CUKUP | E29: KURANG
B30: ='13. Laporan OBE'!Q3 -> 10 | C30: ='13. Laporan OBE'!R3 -> 18 | D30: ='13. Laporan OBE'!S3 -> 1 | E30: ='13. Laporan OBE'!T3 -> 0
B31: ='Matriks Asesmen'!C2&" :" -> CPMK B :
B32: SANGAT BAIK | C32: BAIK | D32: CUKUP | E32: KURANG
B33: ='13. Laporan OBE'!Q4 -> 25 | C33: ='13. Laporan OBE'!R4 -> 3 | D33: ='13. Laporan OBE'!S4 -> 1 | E33: ='13. Laporan OBE'!T4 -> 0
B34: ='Matriks Asesmen'!D2&" :" -> CPMK C :
B35: SANGAT BAIK | C35: BAIK | D35: CUKUP | E35: KURANG
B36: ='13. Laporan OBE'!Q5 -> 22 | C36: ='13. Laporan OBE'!R5 -> 5 | D36: ='13. Laporan OBE'!S5 -> 2 | E36: ='13. Laporan OBE'!T5 -> 0
B37: ='Matriks Asesmen'!E2&" :" -> CPMK D :
B38: SANGAT BAIK | C38: BAIK | D38: CUKUP | E38: KURANG
B39: ='13. Laporan OBE'!Q6 -> 0 | C39: ='13. Laporan OBE'!R6 -> 0 | D39: ='13. Laporan OBE'!S6 -> 0 | E39: ='13. Laporan OBE'!T6 -> 0
B40: ='Matriks Asesmen'!F2&" :" -> CPMK E :
B41: SANGAT BAIK | C41: BAIK | D41: CUKUP | E41: KURANG
B42: ='13. Laporan OBE'!Q7 -> 0 | C42: ='13. Laporan OBE'!R7 -> 0 | D42: ='13. Laporan OBE'!S7 -> 0 | E42: ='13. Laporan OBE'!T7 -> 0
A43: 9 | B43: Distribusi Nilai
B44: Indikator ketercapaian (achieved) adalah apabila 50% jumlah mahasiswa peserta kuliah mendapatkan nilai akhir > 55
B45: Statistik:
B46: Nilai | D46: Jumlah | E46: Persentase
B47: A | D47: =COUNTIF('7.Rekap Nilai'!$K$12:$K$44,"A") -> 0 | E47: =D47/SUM($D$47:$D$55) -> 0
B48: A- | D48: =COUNTIF('7.Rekap Nilai'!$K$12:$K$44,"A-") -> 0 | E48: =D48/SUM($D$47:$D$55) -> 0
...

Sheet 2.RPS
B1: UNIVERSITAS MARITIM RAJA ALI HAJI
B2: ='Master Data'!C15 -> Fakultas …
B3: ='Master Data'!C16 -> Jurusan …
B4: ='Master Data'!C17 -> Program Studi …
A6: RENCANA PEMBELAJARAN SEMESTER
A7: ="Tahun Akademik: " &'Master Data'!C3 -> Tahun Akademik: | D7: ="Semester: "&ROMAN('Master Data'!C7)&" / "&IF(MOD('Master Data'!C7,2),"Ganjil","Genap") -> #VALUE!
A8: ="Nama MK: "&'Master Data'!C4 -> Nama MK: | D8: ="Kode: "&'Master Data'!C5 -> Kode:
A9: ="Kelas: "&'Master Data'!C8 -> Kelas: | D9: ="SKS : "&'Master Data'!C6 -> SKS :
A10: Dosen Pengampu:
A11: 1) | B11: ='Master Data'!C10
A12: =IF('Master Data'!C9>1,"2)","") | B12: =IF('Master Data'!C9>1,'Master Data'!C11,"")
A13: Tautan RPS:

Sheet 3.Kontrak Kuliah
B1: UNIVERSITAS MARITIM RAJA ALI HAJI
B2: ='Master Data'!C15 -> Fakultas …
B3: ='Master Data'!C16 -> Jurusan …
B4: ='Master Data'!C17 -> Program Studi …
A6: KONTRAK PERKULIAHAN
A7: ="Tahun Akademik: " &'Master Data'!C3 -> Tahun Akademik: | D7: ="Semester: "&ROMAN('Master Data'!C7)&" / "&IF(MOD('Master Data'!C7,2),"Ganjil","Genap") -> #VALUE!
A8: ="Nama MK: "&'Master Data'!C4 -> Nama MK: | D8: ="Kode: "&'Master Data'!C5 -> Kode:
A9: ="Kelas: "&'Master Data'!C8 -> Kelas: | D9: ="SKS : "&'Master Data'!C6 -> SKS :
A10: Dosen Pengampu:
A11: 1) | B11: ='Master Data'!C10
A12: =IF('Master Data'!C9>1,"2)","") | B12: =IF('Master Data'!C9>1,'Master Data'!C11,"")
A13: Tautan Kontrak Kuliah:

Sheet 4.Presensi SIPA
B1: UNIVERSITAS MARITIM RAJA ALI HAJI
B2: ='Master Data'!C15 -> Fakultas …
B3: ='Master Data'!C16 -> Jurusan …
B4: ='Master Data'!C17 -> Program Studi …
A6: PRESENSI SIPA
A7: ="Tahun Akademik: " &'Master Data'!C3 -> Tahun Akademik: | D7: ="Semester: "&ROMAN('Master Data'!C7)&" / "&IF(MOD('Master Data'!C7,2),"Ganjil","Genap") -> #VALUE!
A8: ="Nama MK: "&'Master Data'!C4 -> Nama MK: | D8: ="Kode: "&'Master Data'!C5 -> Kode:
A9: ="Kelas: "&'Master Data'!C8 -> Kelas: | D9: ="SKS : "&'Master Data'!C6 -> SKS :
A10: Dosen Pengampu:
A11: 1) | B11: ='Master Data'!C10
A12: =IF('Master Data'!C9>1,"2)","") | B12: =IF('Master Data'!C9>1,'Master Data'!C11,"")
A13: Tautan Presensi SIPA:

Sheet 5.Rekap Presensi
A1: JUMLAH REALISASI KELAS TATAP MUKA SELAMA 1 SEMESTER (TIDAK TERMASUK EVALUASI CPMK)
A2: Realisasi total perkuliahan tatap muka dengan dosen pengampu: | W2: ='Master Data'!C14 | X2: kali tatap muka
A3: IDENTITAS DAN PRESENSI PESERTA KULIAH | D3: REALISASI TATAP MUKA
A4: NIM | B4: Nama | C4: Kelas | D4: P1 | E4: P2 | F4: P3 | G4: P4 | H4: P5 | I4: P6 | J4: P7 | K4: P8 | L4: P9 | M4: P10 | N4: P11 | O4: P12 | P4: P13 | Q4: P14 | R4: P15 | S4: P16 | T4: Hadir | U4: Izin | V4: Sakit | W4: Tanpa Keterangan | X4: Skor Kehadiran (%) | Y4: Keterangan
A5: ='Master Data'!B21 | B5: ='Master Data'!C21 | C5: ='Master Data'!$C$8 | D5: H | E5: TK | F5: H | G5: TK | H5: H | I5: H | J5: H | K5: H | L5: TK | M5: S | N5: TK | O5: H | P5: H | Q5: H | R5: H | S5: H | T5: =COUNTIF(D5:S5,"H") -> 11 | U5: =COUNTIF(D5:S5,"I") -> 0 | V5: =COUNTIF(D5:S5,"S") -> 1 | W5: =COUNTIF(D5:S5,"TK") -> 4 | X5: =IF(W5>=5,0,ROUND(((T5*1 + U5*1 + V5*1)/16)*100,2)) -> 75 | Y5: =IF(W5 >3,"TIDAK BISA UAS","OK") -> TIDAK BISA UAS
A6: ='Master Data'!B22 | B6: ='Master Data'!C22 | C6: ='Master Data'!$C$8 | D6: H | E6: H | F6: H | G6: H | H6: H | I6: H | J6: H | K6: H | L6: H | M6: H | N6: H | O6: H | P6: H | Q6: H | R6: H | S6: H | T6: =COUNTIF(D6:S6,"H") -> 16 | U6: =COUNTIF(D6:S6,"I") -> 0 | V6: =COUNTIF(D6:S6,"S") -> 0 | W6: =COUNTIF(D6:S6,"tk") -> 0 | X6: =IF(W6>=5,0,ROUND(((T6*1 + U6*1 + V6*1)/16)*100,2)) -> 100 | Y6: =IF(W6 >3,"TIDAK BISA UAS","OK") -> OK
A7: ='Master Data'!B23 | B7: ='Master Data'!C23 | C7: ='Master Data'!$C$8 | D7: H | E7: H | F7: H | G7: H | H7: TK | I7: H | J7: H | K7: H | L7: H | M7: TK | N7: H | O7: H | P7: H | Q7: H | R7: H | S7: H | T7: =COUNTIF(D7:S7,"H") -> 13 | U7: =COUNTIF(D7:S7,"I") -> 0 | V7: =COUNTIF(D7:S7,"S") -> 0 | W7: =COUNTIF(D7:S7,"tk") -> 2 | X7: =IF(W7>=5,0,ROUND(((T7*1 + U7*1 + V7*1)/16)*100,2)) -> 81.25 | Y7: =IF(W7 >3,"TIDAK BISA UAS","OK") -> OK
A8: ='Master Data'!B24 | B8: ='Master Data'!C24 | C8: ='Master Data'!$C$8 | D8: TK | E8: H | F8: H | G8: H | H8: H | I8: H | J8: H | K8: H | L8: H | M8: H | N8: H | O8: H | P8: H | Q8: H | R8: H | S8: H | T8: =COUNTIF(D8:S8,"H") -> 15 | U8: =COUNTIF(D8:S8,"I") -> 0 | V8: =COUNTIF(D8:S8,"S") -> 0 | W8: =COUNTIF(D8:S8,"tk") -> 1 | X8: =IF(W8>=5,0,ROUND(((T8*1 + U8*1 + V8*1)/16)*100,2)) -> 93.75 | Y8: =IF(W8 >3,"TIDAK BISA UAS","OK") -> OK
A9: ='Master Data'!B25 | B9: ='Master Data'!C25 | C9: ='Master Data'!$C$8 | D9: H | E9: H | F9: H | G9: H | H9: H | I9: H | J9: H | K9: H | L9: H | M9: TK | N9: H | O9: H | P9: H | Q9: H | R9: H | S9: H | T9: =COUNTIF(D9:S9,"H") -> 15 | U9: =COUNTIF(D9:S9,"I") -> 0 | V9: =COUNTIF(D9:S9,"S") -> 0 | W9: =COUNTIF(D9:S9,"tk") -> 1 | X9: =IF(W9>=5,0,ROUND(((T9*1 + U9*1 + V9*1)/16)*100,2)) -> 93.75 | Y9: =IF(W9 >3,"TIDAK BISA UAS","OK") -> OK
A10: ='Master Data'!B26 | B10: ='Master Data'!C26 | C10: ='Master Data'!$C$8 | D10: H | E10: H | F10: H | G10: H | H10: H | I10: H | J10: H | K10: H | L10: H | M10: S | N10: H | O10: H | P10: H | Q10: H | R10: H | S10: H | T10: =COUNTIF(D10:S10,"H") -> 15 | U10: =COUNTIF(D10:S10,"I") -> 0 | V10: =COUNTIF(D10:S10,"S") -> 1 | W10: =COUNTIF(D10:S10,"tk") -> 0 | X10: =IF(W10>=5,0,ROUND(((T10*1 + U10*1 + V10*1)/16)*100,2)) -> 100 | Y10: =IF(W10 >3,"TIDAK BISA UAS","OK") -> OK
A11: ='Master Data'!B27 | B11: ='Master Data'!C27 | C11: ='Master Data'!$C$8 | D11: H | E11: H | F11: H | G11: H | H11: H | I11: H | J11: H | K11: H | L11: H | M11: H | N11: H | O11: H | P11: H | Q11: H | R11: H | S11: H | T11: =COUNTIF(D11:S11,"H") -> 10 | U11: =COUNTIF(D11:S11,"I") -> 0 | V11: =COUNTIF(D11:S11,"S") -> 0 | W11: =COUNTIF(D11:S11,"tk") -> 0 | X11: =IF(W11>=5,0,ROUND(((T11*1 + U11*1 + V11*1)/16)*100,2)) -> 62.5 | Y11: =IF(W11 >3,"TIDAK BISA UAS","OK") -> OK
A12: ='Master Data'!B28 | B12: ='Master Data'!C28 | C12: ='Master Data'!$C$8 | D12: H | E12: H | F12: H | G12: H | H12: H | I12: H | J12: H | K12: H | L12: H | M12: H | N12: H | O12: H | P12: H | Q12: H | R12: H | S12: H | T12: =COUNTIF(D12:S12,"H") -> 10 | U12: =COUNTIF(D12:S12,"I") -> 0 | V12: =COUNTIF(D12:S12,"S") -> 0 | W12: =COUNTIF(D12:S12,"tk") -> 0 | X12: =IF(W12>=5,0,ROUND(((T12*1 + U12*1 + V12*1)/16)*100,2)) -> 62.5 | Y12: =IF(W12 >3,"TIDAK BISA UAS","OK") -> OK
A13: ='Master Data'!B29 | B13: ='Master Data'!C29 | C13: ='Master Data'!$C$8 | D13: H | E13: H | F13: H | G13: H | H13: H | I13: H | J13: H | K13: H | L13: TK | M13: H | N13: H | O13: H | P13: H | Q13: H | R13: H | S13: H | T13: =COUNTIF(D13:S13,"H") -> 9 | U13: =COUNTIF(D13:S13,"I") -> 0 | V13: =COUNTIF(D13:S13,"S") -> 0 | W13: =COUNTIF(D13:S13,"tk") -> 1 | X13: =IF(W13>=5,0,ROUND(((T13*1 + U13*1 + V13*1)/16)*100,2)) -> 56.25 | Y13: =IF(W13 >3,"TIDAK BISA UAS","OK") -> OK
A14: ='Master Data'!B30 | B14: ='Master Data'!C30 | C14: ='Master Data'!$C$8 | D14: H | E14: H | F14: H | G14: TK | H14: H | I14: H | J14: H | K14: H | L14: H | M14: H | N14: H | O14: H | P14: H | Q14: H | R14: H | S14: H | T14: =COUNTIF(D14:S14,"H") -> 9 | U14: =COUNTIF(D14:S14,"I") -> 0 | V14: =COUNTIF(D14:S14,"S") -> 0 | W14: =COUNTIF(D14:S14,"tk") -> 1 | X14: =IF(W14>=5,0,ROUND(((T14*1 + U14*1 + V14*1)/16)*100,2)) -> 56.25 | Y14: =IF(W14 >3,"TIDAK BISA UAS","OK") -> OK
A15: ='Master Data'!B31 | B15: ='Master Data'!C31 | C15: ='Master Data'!$C$8 | D15: H | E15: H | F15: H | G15: H | H15: H | I15: H | J15: H | K15: H | L15: H | M15: H | N15: H | O15: H | P15: H | Q15: H | R15: H | S15: H | T15: =COUNTIF(D15:S15,"H") -> 16 | U15: =COUNTIF(D15:S15,"I") -> 0 | V15: =COUNTIF(D15:S15,"S") -> 0 | W15: =COUNTIF(D15:S15,"tk") -> 0 | X15: =IF(W15>=5,0,ROUND(((T15*1 + U15*1 + V15*1)/16)*100,2)) -> 100 | Y15: =IF(W15 >3,"TIDAK BISA UAS","OK") -> OK
A16: ='Master Data'!B32 | B16: ='Master Data'!C32 | C16: ='Master Data'!$C$8 | D16: H | E16: H | F16: H | G16: H | H16: TK | I16: H | J16: H | K16: H | L16: H | M16: H | N16: H | O16: H | P16: H | Q16: H | R16: H | S16: H | T16: =COUNTIF(D16:S16,"H") -> 15 | U16: =COUNTIF(D16:S16,"I") -> 0 | V16: =COUNTIF(D16:S16,"S") -> 0 | W16: =COUNTIF(D16:S16,"tk") -> 1 | X16: =IF(W16>=5,0,ROUND(((T16*1 + U16*1 + V16*1)/16)*100,2)) -> 93.75 | Y16: =IF(W16 >3,"TIDAK BISA UAS","OK") -> OK
A17: ='Master Data'!B33 | B17: ='Master Data'!C33 | C17: ='Master Data'!$C$8 | D17: H | E17: H | F17: H | G17: TK | H17: H | I17: H | J17: H | K17: H | L17: H | M17: H | N17: H | O17: H | P17: H | Q17: H | R17: H | S17: H | T17: =COUNTIF(D17:S17,"H") -> 15 | U17: =COUNTIF(D17:S17,"I") -> 0 | V17: =COUNTIF(D17:S17,"S") -> 0 | W17: =COUNTIF(D17:S17,"tk") -> 1 | X17: =IF(W17>=5,0,ROUND(((T17*1 + U17*1 + V17*1)/16)*100,2)) -> 93.75 | Y17: =IF(W17 >3,"TIDAK BISA UAS","OK") -> OK
... A59: ='Master Data'!B75 | B59: ='Master Data'!C75 | C59: ='Master Data'!$C$8 | D59: H | E59: H | F59: H | G59: H | H59: H | I59: H | J59: H | K59: H | L59: H | M59: H | N59: H | O59: H | P59: H | Q59: H | R59: H | S59: H | T59: =COUNTIF(D59:S59,"H") -> 16 | U59: =COUNTIF(D59:S59,"I") -> 0 | V59: =COUNTIF(D59:S59,"S") -> 0 | W59: =COUNTIF(D59:S59,"tk") -> 0 | X59: =IF(W59>=5,0,ROUND(((T59*1 + U59*1 + V59*1)/16)*100,2)) -> 100 | Y59: =IF(W59 >3,"TIDAK BISA UAS","OK") -> OK

Sheet 6.Soal Ujian
B1: UNIVERSITAS MARITIM RAJA ALI HAJI
B2: ='Master Data'!C15 -> Fakultas …
B3: ='Master Data'!C16 -> Jurusan …
B4: ='Master Data'!C17 -> Program Studi …
A6: SOAL UJIAN
A7: ="Tahun Akademik: " &'Master Data'!C3 -> Tahun Akademik: | D7: ="Semester: "&ROMAN('Master Data'!C7)&" / "&IF(MOD('Master Data'!C7,2),"Ganjil","Genap") -> #VALUE!
A8: ="Nama MK: "&'Master Data'!C4 -> Nama MK: | D8: ="Kode: "&'Master Data'!C5 -> Kode:
A9: ="Kelas: "&'Master Data'!C8 -> Kelas: | D9: ="SKS : "&'Master Data'!C6 -> SKS :
A10: Dosen Pengampu:
A11: 1) | B11: ='Master Data'!C10
A12: =IF('Master Data'!C9>1,"2)","") | B12: =IF('Master Data'!C9>1,'Master Data'!C11,"")
A13: Tautan Soal Ujian:

Sheet 7.Rekap Nilai
A1: UNIVERSITAS MARITIM RAJA ALI HAJI
A2: ='Master Data'!C15 -> Fakultas …
A3: ='Master Data'!C16 -> Jurusan …
A4: ='Master Data'!C17 -> Program Studi …
A6: REKAPITULASI NILAI AKHIR MAHASISWA
A7: ="Tahun Akademik: " &'Master Data'!C3 -> Tahun Akademik: | E7: ="Semester: "&ROMAN('Master Data'!C7)&" / "&IF(MOD('Master Data'!C7,2),"Ganjil","Genap") -> #VALUE!
A8: ="Nama MK: "&'Master Data'!C4 -> Nama MK: | E8: ="Kode: "&'Master Data'!C5 -> Kode:
A9: ="Kelas: "&'Master Data'!C8 -> Kelas: | E9: ="SKS : "&'Master Data'!C6 -> SKS :
A10: No | B10: NIM | C10: NAMA | D10: Jumlah Minimal Presensi | E10: ='Matriks Asesmen'!A4 -> UTS | F10: ='Matriks Asesmen'!A5 -> UAS | G10: ='Matriks Asesmen'!A6 -> Keaktifan | H10: ='Matriks Asesmen'!A7 -> Tugas 1 | I10: ='Matriks Asesmen'!A8 -> Tugas 2 | J10: Nilai Angka | K10: Nilai Huruf
E11: ='Matriks Asesmen'!G4 -> 0.25 | F11: ='Matriks Asesmen'!G5 -> 0.3 | G11: ='Matriks Asesmen'!G6 -> 0.15 | H11: ='Matriks Asesmen'!G7 -> 0.05 | I11: ='Matriks Asesmen'!G8 -> 0.05
A12: 1 | B12: ='Master Data'!B21 | C12: ='Master Data'!C21 | D12: ='5.Rekap Presensi'!Y5 -> TIDAK BISA UAS | E12: 48.3 | F12: 70 | G12: 40 | H12: 75 | I12: 85 | J12: 71.71 | K12: =IF(J12>=85,"A",IF(J12>=80,"A-",IF(J12>=75,"B+",IF(J12>=70,"B",IF(J12>=65,"B-",IF(J12>=60,"C+",IF(J12>=55,"C",IF(J12>=40,"D",IF(J12>=0,"E"))))))))) -> B
A13: 2 | B13: ='Master Data'!B22 | C13: ='Master Data'!C22 | D13: ='5.Rekap Presensi'!Y6 -> OK | E13: 80 | F13: 75 | G13: 55 | H13: 80 | I13: 87 | J13: =ROUND(E13*$E$11+F13*$F$11+IF(D13="OK",G13*$G$11,0)+H13*$H$11+I13*$I$11,2) -> 59.1 | K13: =IF(J13>=85,"A",IF(J13>=80,"A-",IF(J13>=75,"B+",IF(J13>=70,"B",IF(J13>=65,"B-",IF(J13>=60,"C+",IF(J13>=55,"C",IF(J13>=40,"D",IF(J13>=0,"E"))))))))) -> C
A14: 3 | B14: ='Master Data'!B23 | C14: ='Master Data'!C23 | D14: ='5.Rekap Presensi'!Y7 -> OK | E14: 56.3 | F14: 46 | G14: 47 | H14: 80 | I14: 85 | J14: =ROUND(E14*$E$11+F14*$F$11+IF(D14="OK",G14*$G$11,0)+H14*$H$11+I14*$I$11,2) -> 43.18 | K14: =IF(J14>=85,"A",IF(J14>=80,"A-",IF(J14>=75,"B+",IF(J14>=70,"B",IF(J14>=65,"B-",IF(J14>=60,"C+",IF(J14>=55,"C",IF(J14>=40,"D",IF(J14>=0,"E"))))))))) -> D
A15: 4 | B15: ='Master Data'!B24 | C15: ='Master Data'!C24 | D15: ='5.Rekap Presensi'!Y8 -> OK | E15: 75 | F15: 75 | G15: 60 | H15: 80 | I15: 85 | J15: =ROUND(E15*$E$11+F15*$F$11+IF(D15="OK",G15*$G$11,0)+H15*$H$11+I15*$I$11,2) -> 58.5 | K15: =IF(J15>=85,"A",IF(J15>=80,"A-",IF(J15>=75,"B+",IF(J15>=70,"B",IF(J15>=65,"B-",IF(J15>=60,"C+",IF(J15>=55,"C",IF(J15>=40,"D",IF(J15>=0,"E"))))))))) -> C
A16: 5 | B16: ='Master Data'!B25 | C16: ='Master Data'!C25 | D16: ='5.Rekap Presensi'!Y9 -> OK | E16: 82.6 | F16: 80 | G16: 52 | H16: 80 | I16: 90 | J16: =ROUND(E16*$E$11+F16*$F$11+IF(D16="OK",G16*$G$11,0)+H16*$H$11+I16*$I$11,2) -> 60.95 | K16: =IF(J16>=85,"A",IF(J16>=80,"A-",IF(J16>=75,"B+",IF(J16>=70,"B",IF(J16>=65,"B-",IF(J16>=60,"C+",IF(J16>=55,"C",IF(J16>=40,"D",IF(J16>=0,"E"))))))))) -> C+
A17: 6 | B17: ='Master Data'!B26 | C17: ='Master Data'!C26 | D17: ='5.Rekap Presensi'!Y10 -> OK | E17: 75 | F17: 75 | G17: 65 | H17: 80 | I17: 85 | J17: =ROUND(E17*$E$11+F17*$F$11+IF(D17="OK",G17*$G$11,0)+H17*$H$11+I17*$I$11,2) -> 59.25 | K17: =IF(J17>=85,"A",IF(J17>=80,"A-",IF(J17>=75,"B+",IF(J17>=70,"B",IF(J17>=65,"B-",IF(J17>=60,"C+",IF(J17>=55,"C",IF(J17>=40,"D",IF(J17>=0,"E"))))))))) -> C
A18: 7 | B18: ='Master Data'!B27 | C18: ='Master Data'!C27 | D18: ='5.Rekap Presensi'!Y11 -> OK | E18: 56.6 | F18: 80 | G18: 55 | H18: 80 | I18: 87 | J18: =ROUND(E18*$E$11+F18*$F$11+IF(D18="OK",G18*$G$11,0)+H18*$H$11+I18*$I$11,2) -> 54.75 | K18: =IF(J18>=85,"A",IF(J18>=80,"A-",IF(J18>=75,"B+",IF(J18>=70,"B",IF(J18>=65,"B-",IF(J18>=60,"C+",IF(J18>=55,"C",IF(J18>=40,"D",IF(J18>=0,"E"))))))))) -> D
A19: 8 | B19: ='Master Data'!B28 | C19: ='Master Data'!C28 | D19: ='5.Rekap Presensi'!Y12 -> OK | E19: 83.3 | F19: 75 | G19: 40 | H19: 80 | I19: 85 | J19: =ROUND(E19*$E$11+F19*$F$11+IF(D19="OK",G19*$G$11,0)+H19*$H$11+I19*$I$11,2) -> 57.58 | K19: =IF(J19>=85,"A",IF(J19>=80,"A-",IF(J19>=75,"B+",IF(J19>=70,"B",IF(J19>=65,"B-",IF(J19>=60,"C+",IF(J19>=55,"C",IF(J19>=40,"D",IF(J19>=0,"E"))))))))) -> C
A20: 9 | B20: ='Master Data'!B29 | C20: ='Master Data'!C29 | D20: ='5.Rekap Presensi'!Y13 -> OK | E20: 75 | F20: 57 | G20: 75 | H20: 80 | I20: 85 | J20: =ROUND(E20*$E$11+F20*$F$11+IF(D20="OK",G20*$G$11,0)+H20*$H$11+I20*$I$11,2) -> 55.35 | K20: =IF(J20>=85,"A",IF(J20>=80,"A-",IF(J20>=75,"B+",IF(J20>=70,"B",IF(J20>=65,"B-",IF(J20>=60,"C+",IF(J20>=55,"C",IF(J20>=40,"D",IF(J20>=0,"E"))))))))) -> C
A21: 10 | B21: ='Master Data'!B30 | C21: ='Master Data'!C30 | D21: ='5.Rekap Presensi'!Y14 -> OK | E21: 80 | F21: 70 | G21: 58 | H21: 80 | I21: 87 | J21: =ROUND(E21*$E$11+F21*$F$11+IF(D21="OK",G21*$G$11,0)+H21*$H$11+I21*$I$11,2) -> 58.05 | K21: =IF(J21>=85,"A",IF(J21>=80,"A-",IF(J21>=75,"B+",IF(J21>=70,"B",IF(J21>=65,"B-",IF(J21>=60,"C+",IF(J21>=55,"C",IF(J21>=40,"D",IF(J21>=0,"E"))))))))) -> C
A22: 11 | B22: ='Master Data'!B31 | C22: ='Master Data'!C31 | D22: ='5.Rekap Presensi'!Y15 -> OK | E22: 83.3 | F22: 80 | G22: 95 | H22: 80 | I22: 90 | J22: =ROUND(E22*$E$11+F22*$F$11+IF(D22="OK",G22*$G$11,0)+H22*$H$11+I22*$I$11,2) -> 67.58 | K22: =IF(J22>=85,"A",IF(J22>=80,"A-",IF(J22>=75,"B+",IF(J22>=70,"B",IF(J22>=65,"B-",IF(J22>=60,"C+",IF(J22>=55,"C",IF(J22>=40,"D",IF(J22>=0,"E"))))))))) -> B-
A23: 12 | B23: ='Master Data'!B32 | C23: ='Master Data'!C32 | D23: ='5.Rekap Presensi'!Y16 -> OK | E23: 80 | F23: 75 | G23: 30 | H23: 80 | I23: 85 | J23: =ROUND(E23*$E$11+F23*$F$11+IF(D23="OK",G23*$G$11,0)+H23*$H$11+I23*$I$11,2) -> 55.25 | K23: =IF(J23>=85,"A",IF(J23>=80,"A-",IF(J23>=75,"B+",IF(J23>=70,"B",IF(J23>=65,"B-",IF(J23>=60,"C+",IF(J23>=55,"C",IF(J23>=40,"D",IF(J23>=0,"E"))))))))) -> C
A24: 13 | B24: ='Master Data'!B33 | C24: ='Master Data'!C33 | D24: ='5.Rekap Presensi'!Y17 -> OK | E24: 58.3 | F24: 80 | G24: 63 | H24: 80 | I24: 87 | J24: =ROUND(E24*$E$11+F24*$F$11+IF(D24="OK",G24*$G$11,0)+H24*$H$11+I24*$I$11,2) -> 56.38 | K24: =IF(J24>=85,"A",IF(J24>=80,"A-",IF(J24>=75,"B+",IF(J24>=70,"B",IF(J24>=65,"B-",IF(J24>=60,"C+",IF(J24>=55,"C",IF(J24>=40,"D",IF(J24>=0,"E"))))))))) -> C
... A43: 32 | B43: ='Master Data'!B52 | C43: ='Master Data'!C52 | D43: ='5.Rekap Presensi'!Y36 -> OK | E43: 82.7 | F43: 80 | G43: 45 | H43: 80 | I43: 90 | J43: =ROUND(E43*$E$11+F43*$F$11+IF(D43="OK",G43*$G$11,0)+H43*$H$11+I43*$I$11,2) -> 59.93 | K43: =IF(J43>=85,"A",IF(J43>=80,"A-",IF(J43>=75,"B+",IF(J43>=70,"B",IF(J43>=65,"B-",IF(J43>=60,"C+",IF(J43>=55,"C",IF(J43>=40,"D",IF(J43>=0,"E"))))))))) -> C

Sheet 8.CPMK A
A1: ="PEMBOBOTAN NILAI ASESMEN "&'Matriks Asesmen'!B2 -> PEMBOBOTAN NILAI ASESMEN CPMK A
A2: ="Isikan bobot nilai tiap Asesmen "&M1&". Jumlah total bobot nilai dari seluruh asesmen harus sama dengan bobot nilai "&M1 -> Isikan bobot nilai tiap Asesmen . Jumlah total bobot nilai dari seluruh asesmen harus sama dengan bobot nilai
A3: ="Bobot "&'Matriks Asesmen'!B2&" terhadap total jumlah seluruh CPMK:" -> Bobot CPMK A terhadap total jumlah seluruh CPMK: | K3: =SUM(K4:K8) -> 0.3
A4: Bobot Penilaian-1 | H4: ='Matriks Asesmen'!A4 -> UTS | K4: ='Matriks Asesmen'!B4 -> 0.1
A5: Bobot Penilaian-2 | H5: ='Matriks Asesmen'!A5 -> UAS | K5: ='Matriks Asesmen'!B5 -> 0.1
A6: Bobot Penilaian-3 | H6: ='Matriks Asesmen'!A6 -> Keaktifan | K6: ='Matriks Asesmen'!B6 -> 0.05
A7: Bobot Penilaian-4 | H7: ='Matriks Asesmen'!A7 -> Tugas 1 | K7: ='Matriks Asesmen'!B7 -> 0.05
A8: Bobot Penilaian-5 | H8: ='Matriks Asesmen'!A8 -> Tugas 2 | K8: ='Matriks Asesmen'!B8
A9: Bobot Penilaian-6 | H9: ='Matriks Asesmen'!A9 -> Tugas 3 | K9: ='Matriks Asesmen'!B9
A10: Bobot Penilaian-7 | H10: ='Matriks Asesmen'!A10 -> Tugas 4 | K10: ='Matriks Asesmen'!B10
A11: Bobot Penilaian-8 | H11: ='Matriks Asesmen'!A11 -> (bentuk penilaian lainnya) | K11: ='Matriks Asesmen'!B11
A12: Bobot Penilaian-9 | H12: ='Matriks Asesmen'!A12 -> (bentuk penilaian lainnya) | K12: ='Matriks Asesmen'!B12
A13: Bobot Penilaian-10 | H13: ='Matriks Asesmen'!A13 -> (bentuk penilaian lainnya) | K13: ='Matriks Asesmen'!B13
A15: ="ASESMEN CAPAIAN PEMBELAJARAN "&'Matriks Asesmen'!B2 -> ASESMEN CAPAIAN PEMBELAJARAN CPMK A
A16: No | B16: NIM | C16: NAMA | D16: ='7.Rekap Nilai'!D10 -> Jumlah Minimal Presensi | E16: ='7.Rekap Nilai'!E10 -> UTS | F16: ='7.Rekap Nilai'!F10 -> UAS | G16: ='7.Rekap Nilai'!G10 -> Keaktifan | H16: ='7.Rekap Nilai'!H10 -> Tugas 1 | I16: ='7.Rekap Nilai'!I10 -> Tugas 2 | J16: NILAI CAPAIAN | K16: STATUS KELULUSAN CPMK
A17: 1 | B17: ='Master Data'!B21 | C17: ='Master Data'!C21 | D17: ='7.Rekap Nilai'!D12 -> TIDAK BISA UAS | E17: ='7.Rekap Nilai'!E12 -> 48.3 | F17: ='7.Rekap Nilai'!F12 -> 70 | G17: ='7.Rekap Nilai'!G12 -> 40 | H17: ='7.Rekap Nilai'!H12 -> 75 | I17: ='7.Rekap Nilai'!I12 -> 85 | J17: =(E17*$K$4+F17*$K$5+IF(D17="OK",G17*$K$7,0)+H17*$K$6+I17*$K$8)/$K$3 -> 51.933333 | K17: =IF(J17>=55,"LULUS ","TIDAK LULUS ") -> TIDAK LULUS
A18: 2 | B18: ='Master Data'!B22 | C18: ='Master Data'!C22 | D18: ='7.Rekap Nilai'!D13 -> OK | E18: ='7.Rekap Nilai'!E13 -> 80 | F18: ='7.Rekap Nilai'!F13 -> 75 | G18: ='7.Rekap Nilai'!G13 -> 55 | H18: ='7.Rekap Nilai'!H13 -> 80 | I18: ='7.Rekap Nilai'!I13 -> 87 | J18: =(E18*$K$4+F18*$K$5+IF(D18="OK",G18*$K$7,0)+H18*$K$6+I18*$K$8)/$K$3 -> 74.166667 | K18: =IF(J18>=55,"LULUS ","TIDAK LULUS ") -> LULUS
A19: 3 | B19: ='Master Data'!B23 | C19: ='Master Data'!C23 | D19: ='7.Rekap Nilai'!D14 -> OK | E19: ='7.Rekap Nilai'!E14 -> 56.3 | F19: ='7.Rekap Nilai'!F14 -> 46 | G19: ='7.Rekap Nilai'!G14 -> 47 | H19: ='7.Rekap Nilai'!H14 -> 80 | I19: ='7.Rekap Nilai'!I14 -> 85 | J19: =(E19*$K$4+F19*$K$5+IF(D19="OK",G19*$K$7,0)+H19*$K$6+I19*$K$8)/$K$3 -> 55.266667 | K19: =IF(J19>=55,"LULUS ","TIDAK LULUS ") -> LULUS
A20: 4 | B20: ='Master Data'!B24 | C20: ='Master Data'!C24 | D20: ='7.Rekap Nilai'!D15 -> OK | E20: ='7.Rekap Nilai'!E15 -> 75 | F20: ='7.Rekap Nilai'!F15 -> 75 | G20: ='7.Rekap Nilai'!G15 -> 60 | H20: ='7.Rekap Nilai'!H15 -> 80 | I20: ='7.Rekap Nilai'!I15 -> 85 | J20: =(E20*$K$4+F20*$K$5+IF(D20="OK",G20*$K$7,0)+H20*$K$6+I20*$K$8)/$K$3 -> 73.333333 | K20: =IF(J20>=55,"LULUS ","TIDAK LULUS ") -> LULUS
A21: 5 | B21: ='Master Data'!B25 | C21: ='Master Data'!C25 | D21: ='7.Rekap Nilai'!D16 -> OK | E21: ='7.Rekap Nilai'!E16 -> 82.6 | F21: ='7.Rekap Nilai'!F16 -> 80 | G21: ='7.Rekap Nilai'!G16 -> 52 | H21: ='7.Rekap Nilai'!H16 -> 80 | I21: ='7.Rekap Nilai'!I16 -> 90 | J21: =(E21*$K$4+F21*$K$5+IF(D21="OK",G21*$K$7,0)+H21*$K$6+I21*$K$8)/$K$3 -> 76.2 | K21: =IF(J21>=55,"LULUS ","TIDAK LULUS ") -> LULUS
A22: 6 | B22: ='Master Data'!B26 | C22: ='Master Data'!C26 | D22: ='7.Rekap Nilai'!D17 -> OK | E22: ='7.Rekap Nilai'!E17 -> 75 | F22: ='7.Rekap Nilai'!F17 -> 75 | G22: ='7.Rekap Nilai'!G17 -> 65 | H22: ='7.Rekap Nilai'!H17 -> 80 | I22: ='7.Rekap Nilai'!I17 -> 85 | J22: =(E22*$K$4+F22*$K$5+IF(D22="OK",G22*$K$7,0)+H22*$K$6+I22*$K$8)/$K$3 -> 74.166667 | K22: =IF(J22>=55,"LULUS ","TIDAK LULUS ") -> LULUS
A23: 7 | B23: ='Master Data'!B27 | C23: ='Master Data'!C27 | D23: ='7.Rekap Nilai'!D18 -> OK | E23: ='7.Rekap Nilai'!E18 -> 56.6 | F23: ='7.Rekap Nilai'!F18 -> 80 | G23: ='7.Rekap Nilai'!G18 -> 55 | H23: ='7.Rekap Nilai'!H18 -> 80 | I23: ='7.Rekap Nilai'!I18 -> 87 | J23: =(E23*$K$4+F23*$K$5+IF(D23="OK",G23*$K$7,0)+H23*$K$6+I23*$K$8)/$K$3 -> 68.033333 | K23: =IF(J23>=55,"LULUS ","TIDAK LULUS ") -> LULUS
A24: 8 | B24: ='Master Data'!B28 | C24: ='Master Data'!C28 | D24: ='7.Rekap Nilai'!D19 -> OK | E24: ='7.Rekap Nilai'!E19 -> 83.3 | F24: ='7.Rekap Nilai'!F19 -> 75 | G24: ='7.Rekap Nilai'!G19 -> 40 | H24: ='7.Rekap Nilai'!H19 -> 80 | I24: ='7.Rekap Nilai'!I19 -> 85 | J24: =(E24*$K$4+F24*$K$5+IF(D24="OK",G24*$K$7,0)+H24*$K$6+I24*$K$8)/$K$3 -> 72.766667 | K24: =IF(J24>=55,"LULUS ","TIDAK LULUS ") -> LULUS
A25: 9 | B25: ='Master Data'!B29 | C25: ='Master Data'!C29 | D25: ='7.Rekap Nilai'!D20 -> OK | E25: ='7.Rekap Nilai'!E20 -> 75 | F25: ='7.Rekap Nilai'!F20 -> 57 | G25: ='7.Rekap Nilai'!G20 -> 75 | H25: ='7.Rekap Nilai'!H20 -> 80 | I25: ='7.Rekap Nilai'!I20 -> 85 | J25: =(E25*$K$4+F25*$K$5+IF(D25="OK",G25*$K$7,0)+H25*$K$6+I25*$K$8)/$K$3 -> 69.833333 | K25: =IF(J25>=55,"LULUS ","TIDAK LULUS ") -> LULUS
A26: 10 | B26: ='Master Data'!B30 | C26: ='Master Data'!C30 | D26: ='7.Rekap Nilai'!D21 -> OK | E26: ='7.Rekap Nilai'!E21 -> 80 | F26: ='7.Rekap Nilai'!F21 -> 70 | G26: ='7.Rekap Nilai'!G21 -> 58 | H26: ='7.Rekap Nilai'!H21 -> 80 | I26: ='7.Rekap Nilai'!I21 -> 87 | J26: =(E26*$K$4+F26*$K$5+IF(D26="OK",G26*$K$7,0)+H26*$K$6+I26*$K$8)/$K$3 -> 73 | K26: =IF(J26>=55,"LULUS ","TIDAK LULUS ") -> LULUS
A27: 11 | B27: ='Master Data'!B31 | C27: ='Master Data'!C31 | D27: ='7.Rekap Nilai'!D22 -> OK | E27: ='7.Rekap Nilai'!E22 -> 83.3 | F27: ='7.Rekap Nilai'!F22 -> 80 | G27: ='7.Rekap Nilai'!G22 -> 95 | H27: ='7.Rekap Nilai'!H22 -> 80 | I27: ='7.Rekap Nilai'!I22 -> 90 | J27: =(E27*$K$4+F27*$K$5+IF(D27="OK",G27*$K$7,0)+H27*$K$6+I27*$K$8)/$K$3 -> 83.6 | K27: =IF(J27>=55,"LULUS ","TIDAK LULUS ") -> LULUS
A28: 12 | B28: ='Master Data'!B32 | C28: ='Master Data'!C32 | D28: ='7.Rekap Nilai'!D23 -> OK | E28: ='7.Rekap Nilai'!E23 -> 80 | F28: ='7.Rekap Nilai'!F23 -> 75 | G28: ='7.Rekap Nilai'!G23 -> 30 | H28: ='7.Rekap Nilai'!H23 -> 80 | I28: ='7.Rekap Nilai'!I23 -> 85 | J28: =(E28*$K$4+F28*$K$5+IF(D28="OK",G28*$K$7,0)+H28*$K$6+I28*$K$8)/$K$3 -> 70 | K28: =IF(J28>=55,"LULUS ","TIDAK LULUS ") -> LULUS
... A48: 32 | B48: ='Master Data'!B52 | C48: ='Master Data'!C52 | D48: ='7.Rekap Nilai'!D43 -> OK | E48: ='7.Rekap Nilai'!E43 -> 82.7 | F48: ='7.Rekap Nilai'!F43 -> 80 | G48: ='7.Rekap Nilai'!G43 -> 45 | H48: ='7.Rekap Nilai'!H43 -> 80 | I48: ='7.Rekap Nilai'!I43 -> 90 | J48: =(E48*$K$4+F48*$K$5+IF(D48="OK",G48*$K$7,0)+H48*$K$6+I48*$K$8)/$K$3 -> 75.066667 | K48: =IF(J48>=55,"LULUS ","TIDAK LULUS ") -> LULUS

Sheet 9.CPMK B
A1: ="PEMBOBOTAN NILAI ASESMEN "&'Matriks Asesmen'!C2 -> PEMBOBOTAN NILAI ASESMEN CPMK B
A2: ="Isikan bobot nilai tiap Asesmen "&M1&". Jumlah total bobot nilai dari seluruh asesmen harus sama dengan bobot nilai "&M1 -> Isikan bobot nilai tiap Asesmen . Jumlah total bobot nilai dari seluruh asesmen harus sama dengan bobot nilai
A3: ="Bobot "&'Matriks Asesmen'!C2&" terhadap total jumlah seluruh CPMK:" -> Bobot CPMK B terhadap total jumlah seluruh CPMK: | K3: =SUM(K4:K8) -> 0.35
A4: Bobot Penilaian-1 | H4: ='Matriks Asesmen'!A4 -> UTS | K4: ='Matriks Asesmen'!C4 -> 0.15
A5: Bobot Penilaian-2 | H5: ='Matriks Asesmen'!A5 -> UAS | K5: ='Matriks Asesmen'!C5 -> 0.1
A6: Bobot Penilaian-3 | H6: ='Matriks Asesmen'!A6 -> Keaktifan | K6: ='Matriks Asesmen'!C6 -> 0.05
A7: Bobot Penilaian-4 | H7: ='Matriks Asesmen'!A7 -> Tugas 1 | K7: ='Matriks Asesmen'!C7
A8: Bobot Penilaian-5 | H8: ='Matriks Asesmen'!A8 -> Tugas 2 | K8: ='Matriks Asesmen'!C8 -> 0.05
A9: Bobot Penilaian-6 | H9: ='Matriks Asesmen'!A9 -> Tugas 3 | K9: ='Matriks Asesmen'!C9 -> 0.05
A10: Bobot Penilaian-7 | H10: ='Matriks Asesmen'!A10 -> Tugas 4 | K10: ='Matriks Asesmen'!C10 -> 0.05
A11: Bobot Penilaian-8 | H11: ='Matriks Asesmen'!A11 -> (bentuk penilaian lainnya) | K11: ='Matriks Asesmen'!C11
A12: Bobot Penilaian-9 | H12: ='Matriks Asesmen'!A12 -> (bentuk penilaian lainnya) | K12: ='Matriks Asesmen'!C12
A13: Bobot Penilaian-10 | H13: ='Matriks Asesmen'!A13 -> (bentuk penilaian lainnya) | K13: ='Matriks Asesmen'!C13
A15: ="ASESMEN CAPAIAN PEMBELAJARAN "&'Matriks Asesmen'!C2 -> ASESMEN CAPAIAN PEMBELAJARAN CPMK B
A16: No | B16: NIM | C16: NAMA | D16: ='7.Rekap Nilai'!D10 -> Jumlah Minimal Presensi | E16: ='7.Rekap Nilai'!E10 -> UTS | F16: ='7.Rekap Nilai'!F10 -> UAS | G16: ='7.Rekap Nilai'!G10 -> Keaktifan | H16: ='7.Rekap Nilai'!H10 -> Tugas 1 | I16: ='7.Rekap Nilai'!I10 -> Tugas 2 | J16: NILAI CAPAIAN | K16: STATUS KELULUSAN CPMK
A17: 1 | B17: ='Master Data'!B21 | C17: ='Master Data'!C21 | D17: ='7.Rekap Nilai'!D12 -> TIDAK BISA UAS | E17: ='7.Rekap Nilai'!E12 -> 48.3 | F17: ='7.Rekap Nilai'!F12 -> 70 | G17: ='7.Rekap Nilai'!G12 -> 40 | H17: ='7.Rekap Nilai'!H12 -> 75 | I17: ='7.Rekap Nilai'!I12 -> 85 | J17: =(E17*$K$4+F17*$K$5+IF(D17="OK",G17*$K$7,0)+H17*$K$6+I17*$K$8)/$K$3 -> 63.557143 | K17: =IF(J17>=55,"LULUS ","TIDAK LULUS ") -> LULUS
A18: 2 | B18: ='Master Data'!B22 | C18: ='Master Data'!C22 | D18: ='7.Rekap Nilai'!D13 -> OK | E18: ='7.Rekap Nilai'!E13 -> 80 | F18: ='7.Rekap Nilai'!F13 -> 75 | G18: ='7.Rekap Nilai'!G13 -> 55 | H18: ='7.Rekap Nilai'!H13 -> 80 | I18: ='7.Rekap Nilai'!I13 -> 87 | J18: =(E18*$K$4+F18*$K$5+IF(D18="OK",G18*$K$7,0)+H18*$K$6+I18*$K$8)/$K$3 -> 79.571429 | K18: =IF(J18>=55,"LULUS ","TIDAK LULUS ") -> LULUS
A19: 3 | B19: ='Master Data'!B23 | C19: ='Master Data'!C23 | D19: ='7.Rekap Nilai'!D14 -> OK | E19: ='7.Rekap Nilai'!E14 -> 56.3 | F19: ='7.Rekap Nilai'!F14 -> 46 | G19: ='7.Rekap Nilai'!G14 -> 47 | H19: ='7.Rekap Nilai'!H14 -> 80 | I19: ='7.Rekap Nilai'!I14 -> 85 | J19: =(E19*$K$4+F19*$K$5+IF(D19="OK",G19*$K$7,0)+H19*$K$6+I19*$K$8)/$K$3 -> 60.842857 | K19: =IF(J19>=55,"LULUS ","TIDAK LULUS ") -> LULUS
A20: 4 | B20: ='Master Data'!B24 | C20: ='Master Data'!C24 | D20: ='7.Rekap Nilai'!D15 -> OK | E20: ='7.Rekap Nilai'!E15 -> 75 | F20: ='7.Rekap Nilai'!F15 -> 75 | G20: ='7.Rekap Nilai'!G15 -> 60 | H20: ='7.Rekap Nilai'!H15 -> 80 | I20: ='7.Rekap Nilai'!I15 -> 85 | J20: =(E20*$K$4+F20*$K$5+IF(D20="OK",G20*$K$7,0)+H20*$K$6+I20*$K$8)/$K$3 -> 77.142857 | K20: =IF(J20>=55,"LULUS ","TIDAK LULUS ") -> LULUS
A21: 5 | B21: ='Master Data'!B25 | C21: ='Master Data'!C25 | D21: ='7.Rekap Nilai'!D16 -> OK | E21: ='7.Rekap Nilai'!E16 -> 82.6 | F21: ='7.Rekap Nilai'!F16 -> 80 | G21: ='7.Rekap Nilai'!G16 -> 52 | H21: ='7.Rekap Nilai'!H16 -> 80 | I21: ='7.Rekap Nilai'!I16 -> 90 | J21: =(E21*$K$4+F21*$K$5+IF(D21="OK",G21*$K$7,0)+H21*$K$6+I21*$K$8)/$K$3 -> 82.542857 | K21: =IF(J21>=55,"LULUS ","TIDAK LULUS ") -> LULUS
A22: 6 | B22: ='Master Data'!B26 | C22: ='Master Data'!C26 | D22: ='7.Rekap Nilai'!D17 -> OK | E22: ='7.Rekap Nilai'!E17 -> 75 | F22: ='7.Rekap Nilai'!F17 -> 75 | G22: ='7.Rekap Nilai'!G17 -> 65 | H22: ='7.Rekap Nilai'!H17 -> 80 | I22: ='7.Rekap Nilai'!I17 -> 85 | J22: =(E22*$K$4+F22*$K$5+IF(D22="OK",G22*$K$7,0)+H22*$K$6+I22*$K$8)/$K$3 -> 77.142857 | K22: =IF(J22>=55,"LULUS ","TIDAK LULUS ") -> LULUS
A23: 7 | B23: ='Master Data'!B27 | C23: ='Master Data'!C27 | D23: ='7.Rekap Nilai'!D18 -> OK | E23: ='7.Rekap Nilai'!E18 -> 56.6 | F23: ='7.Rekap Nilai'!F18 -> 80 | G23: ='7.Rekap Nilai'!G18 -> 55 | H23: ='7.Rekap Nilai'!H18 -> 80 | I23: ='7.Rekap Nilai'!I18 -> 87 | J23: =(E23*$K$4+F23*$K$5+IF(D23="OK",G23*$K$7,0)+H23*$K$6+I23*$K$8)/$K$3 -> 70.971429 | K23: =IF(J23>=55,"LULUS ","TIDAK LULUS ") -> LULUS
A24: 8 | B24: ='Master Data'!B28 | C24: ='Master Data'!C28 | D24: ='7.Rekap Nilai'!D19 -> OK | E24: ='7.Rekap Nilai'!E19 -> 83.3 | F24: ='7.Rekap Nilai'!F19 -> 75 | G24: ='7.Rekap Nilai'!G19 -> 40 | H24: ='7.Rekap Nilai'!H19 -> 80 | I24: ='7.Rekap Nilai'!I19 -> 85 | J24: =(E24*$K$4+F24*$K$5+IF(D24="OK",G24*$K$7,0)+H24*$K$6+I24*$K$8)/$K$3 -> 80.7 | K24: =IF(J24>=55,"LULUS ","TIDAK LULUS ") -> LULUS
A25: 9 | B25: ='Master Data'!B29 | C25: ='Master Data'!C29 | D25: ='7.Rekap Nilai'!D20 -> OK | E25: ='7.Rekap Nilai'!E20 -> 75 | F25: ='7.Rekap Nilai'!F20 -> 57 | G25: ='7.Rekap Nilai'!G20 -> 75 | H25: ='7.Rekap Nilai'!H20 -> 80 | I25: ='7.Rekap Nilai'!I20 -> 85 | J25: =(E25*$K$4+F25*$K$5+IF(D25="OK",G25*$K$7,0)+H25*$K$6+I25*$K$8)/$K$3 -> 72 | K25: =IF(J25>=55,"LULUS ","TIDAK LULUS ") -> LULUS
A26: 10 | B26: ='Master Data'!B30 | C26: ='Master Data'!C30 | D26: ='7.Rekap Nilai'!D21 -> OK | E26: ='7.Rekap Nilai'!E21 -> 80 | F26: ='7.Rekap Nilai'!F21 -> 70 | G26: ='7.Rekap Nilai'!G21 -> 58 | H26: ='7.Rekap Nilai'!H21 -> 80 | I26: ='7.Rekap Nilai'!I21 -> 87 | J26: =(E26*$K$4+F26*$K$5+IF(D26="OK",G26*$K$7,0)+H26*$K$6+I26*$K$8)/$K$3 -> 78.142857 | K26: =IF(J26>=55,"LULUS ","TIDAK LULUS ") -> LULUS
A27: 11 | B27: ='Master Data'!B31 | C27: ='Master Data'!C31 | D27: ='7.Rekap Nilai'!D22 -> OK | E27: ='7.Rekap Nilai'!E22 -> 83.3 | F27: ='7.Rekap Nilai'!F22 -> 80 | G27: ='7.Rekap Nilai'!G22 -> 95 | H27: ='7.Rekap Nilai'!H22 -> 80 | I27: ='7.Rekap Nilai'!I22 -> 90 | J27: =(E27*$K$4+F27*$K$5+IF(D27="OK",G27*$K$7,0)+H27*$K$6+I27*$K$8)/$K$3 -> 82.842857 | K27: =IF(J27>=55,"LULUS ","TIDAK LULUS ") -> LULUS
A28: 12 | B28: ='Master Data'!B32 | C28: ='Master Data'!C32 | D28: ='7.Rekap Nilai'!D23 -> OK | E28: ='7.Rekap Nilai'!E23 -> 80 | F28: ='7.Rekap Nilai'!F23 -> 75 | G28: ='7.Rekap Nilai'!G23 -> 30 | H28: ='7.Rekap Nilai'!H23 -> 80 | I28: ='7.Rekap Nilai'!I23 -> 85 | J28: =(E28*$K$4+F28*$K$5+IF(D28="OK",G28*$K$7,0)+H28*$K$6+I28*$K$8)/$K$3 -> 79.285714 | K28: =IF(J28>=55,"LULUS ","TIDAK LULUS ") -> LULUS
... A48: 32 | B48: ='Master Data'!B52 | C48: ='Master Data'!C52 | D48: ='7.Rekap Nilai'!D43 -> OK | E48: ='7.Rekap Nilai'!E43 -> 82.7 | F48: ='7.Rekap Nilai'!F43 -> 80 | G48: ='7.Rekap Nilai'!G43 -> 45 | H48: ='7.Rekap Nilai'!H43 -> 80 | I48: ='7.Rekap Nilai'!I43 -> 90 | J48: =(E48*$K$4+F48*$K$5+IF(D48="OK",G48*$K$7,0)+H48*$K$6+I48*$K$8)/$K$3 -> 82.585714 | K48: =IF(J48>=55,"LULUS ","TIDAK LULUS ") -> LULUS

Sheet 10.CPMK C
A1: ="PEMBOBOTAN NILAI ASESMEN "&'Matriks Asesmen'!D2 -> PEMBOBOTAN NILAI ASESMEN CPMK C
A2: ="Isikan bobot nilai tiap Asesmen "&#REF!&". Jumlah total bobot nilai dari seluruh asesmen harus sama dengan bobot nilai "&#REF! -> #REF!
A3: ="Bobot "&'Matriks Asesmen'!D2&" terhadap total jumlah seluruh CPMK:" -> Bobot CPMK C terhadap total jumlah seluruh CPMK: | K3: =SUM(K4:K8) -> 0.15
A4: Bobot Penilaian-1 | G4: ='Matriks Asesmen'!A4 -> UTS | K4: ='Matriks Asesmen'!D4
A5: Bobot Penilaian-2 | G5: ='Matriks Asesmen'!A5 -> UAS | K5: ='Matriks Asesmen'!D5 -> 0.1
A6: Bobot Penilaian-3 | G6: ='Matriks Asesmen'!A6 -> Keaktifan | K6: ='Matriks Asesmen'!D6 -> 0.05
A7: Bobot Penilaian-4 | G7: ='Matriks Asesmen'!A7 -> Tugas 1 | K7: ='Matriks Asesmen'!D7
A8: Bobot Penilaian-5 | G8: ='Matriks Asesmen'!A8 -> Tugas 2 | K8: ='Matriks Asesmen'!D8
A9: Bobot Penilaian-6 | G9: ='Matriks Asesmen'!A9 -> Tugas 3 | K9: ='Matriks Asesmen'!D9 -> 0.05
A10: Bobot Penilaian-7 | G10: ='Matriks Asesmen'!A10 -> Tugas 4 | K10: ='Matriks Asesmen'!D10 -> 0.05
A11: Bobot Penilaian-8 | G11: ='Matriks Asesmen'!A11 -> (bentuk penilaian lainnya) | K11: ='Matriks Asesmen'!D11
A12: Bobot Penilaian-9 | G12: ='Matriks Asesmen'!A12 -> (bentuk penilaian lainnya) | K12: ='Matriks Asesmen'!D12
A13: Bobot Penilaian-10 | G13: ='Matriks Asesmen'!A13 -> (bentuk penilaian lainnya) | K13: ='Matriks Asesmen'!D13
A15: ="ASESMEN CAPAIAN PEMBELAJARAN "&'Matriks Asesmen'!D2 -> ASESMEN CAPAIAN PEMBELAJARAN CPMK C
A16: No | B16: NIM | C16: NAMA | D16: ='7.Rekap Nilai'!D10 -> Jumlah Minimal Presensi | E16: ='7.Rekap Nilai'!E10 -> UTS | F16: ='7.Rekap Nilai'!F10 -> UAS | G16: ='7.Rekap Nilai'!G10 -> Keaktifan | H16: ='7.Rekap Nilai'!H10 -> Tugas 1 | I16: ='7.Rekap Nilai'!I10 -> Tugas 2 | J16: NILAI CAPAIAN | K16: STATUS KELULUSAN CPMK
A17: 1 | B17: ='Master Data'!B21 | C17: ='Master Data'!C21 | D17: ='7.Rekap Nilai'!D12 -> TIDAK BISA UAS | E17: ='7.Rekap Nilai'!E12 -> 48.3 | F17: ='7.Rekap Nilai'!F12 -> 70 | G17: ='7.Rekap Nilai'!G12 -> 40 | H17: ='7.Rekap Nilai'!H12 -> 75 | I17: ='7.Rekap Nilai'!I12 -> 85 | J17: =(E17*$K$4+F17*$K$5+IF(D17="OK",G17*$K$7,0)+H17*$K$6+I17*$K$8)/$K$3 -> 71.666667 | K17: =IF(J17>=55,"LULUS ","TIDAK LULUS ") -> LULUS
A18: 2 | B18: ='Master Data'!B22 | C18: ='Master Data'!C22 | D18: ='7.Rekap Nilai'!D13 -> OK | E18: ='7.Rekap Nilai'!E13 -> 80 | F18: ='7.Rekap Nilai'!F13 -> 75 | G18: ='7.Rekap Nilai'!G13 -> 55 | H18: ='7.Rekap Nilai'!H13 -> 80 | I18: ='7.Rekap Nilai'!I13 -> 87 | J18: =(E18*$K$4+F18*$K$5+IF(D18="OK",G18*$K$7,0)+H18*$K$6+I18*$K$8)/$K$3 -> 76.666667 | K18: =IF(J18>=55,"LULUS ","TIDAK LULUS ") -> LULUS
A19: 3 | B19: ='Master Data'!B23 | C19: ='Master Data'!C23 | D19: ='7.Rekap Nilai'!D14 -> OK | E19: ='7.Rekap Nilai'!E14 -> 56.3 | F19: ='7.Rekap Nilai'!F14 -> 46 | G19: ='7.Rekap Nilai'!G14 -> 47 | H19: ='7.Rekap Nilai'!H14 -> 80 | I19: ='7.Rekap Nilai'!I14 -> 85 | J19: =(E19*$K$4+F19*$K$5+IF(D19="OK",G19*$K$7,0)+H19*$K$6+I19*$K$8)/$K$3 -> 57.333333 | K19: =IF(J19>=55,"LULUS ","TIDAK LULUS ") -> LULUS
A20: 4 | B20: ='Master Data'!B24 | C20: ='Master Data'!C24 | D20: ='7.Rekap Nilai'!D15 -> OK | E20: ='7.Rekap Nilai'!E15 -> 75 | F20: ='7.Rekap Nilai'!F15 -> 75 | G20: ='7.Rekap Nilai'!G15 -> 60 | H20: ='7.Rekap Nilai'!H15 -> 80 | I20: ='7.Rekap Nilai'!I15 -> 85 | J20: =(E20*$K$4+F20*$K$5+IF(D20="OK",G20*$K$7,0)+H20*$K$6+I20*$K$8)/$K$3 -> 76.666667 | K20: =IF(J20>=55,"LULUS ","TIDAK LULUS ") -> LULUS
A21: 5 | B21: ='Master Data'!B25 | C21: ='Master Data'!C25 | D21: ='7.Rekap Nilai'!D16 -> OK | E21: ='7.Rekap Nilai'!E16 -> 82.6 | F21: ='7.Rekap Nilai'!F16 -> 80 | G21: ='7.Rekap Nilai'!G16 -> 52 | H21: ='7.Rekap Nilai'!H16 -> 80 | I21: ='7.Rekap Nilai'!I16 -> 90 | J21: =(E21*$K$4+F21*$K$5+IF(D21="OK",G21*$K$7,0)+H21*$K$6+I21*$K$8)/$K$3 -> 80 | K21: =IF(J21>=55,"LULUS ","TIDAK LULUS ") -> LULUS
A22: 6 | B22: ='Master Data'!B26 | C22: ='Master Data'!C26 | D22: ='7.Rekap Nilai'!D17 -> OK | E22: ='7.Rekap Nilai'!E17 -> 75 | F22: ='7.Rekap Nilai'!F17 -> 75 | G22: ='7.Rekap Nilai'!G17 -> 65 | H22: ='7.Rekap Nilai'!H17 -> 80 | I22: ='7.Rekap Nilai'!I17 -> 85 | J22: =(E22*$K$4+F22*$K$5+IF(D22="OK",G22*$K$7,0)+H22*$K$6+I22*$K$8)/$K$3 -> 76.666667 | K22: =IF(J22>=55,"LULUS ","TIDAK LULUS ") -> LULUS
A23: 7 | B23: ='Master Data'!B27 | C23: ='Master Data'!C27 | D23: ='7.Rekap Nilai'!D18 -> OK | E23: ='7.Rekap Nilai'!E18 -> 56.6 | F23: ='7.Rekap Nilai'!F18 -> 80 | G23: ='7.Rekap Nilai'!G18 -> 55 | H23: ='7.Rekap Nilai'!H18 -> 80 | I23: ='7.Rekap Nilai'!I18 -> 87 | J23: =(E23*$K$4+F23*$K$5+IF(D23="OK",G23*$K$7,0)+H23*$K$6+I23*$K$8)/$K$3 -> 80 | K23: =IF(J23>=55,"LULUS ","TIDAK LULUS ") -> LULUS
A24: 8 | B24: ='Master Data'!B28 | C24: ='Master Data'!C28 | D24: ='7.Rekap Nilai'!D19 -> OK | E24: ='7.Rekap Nilai'!E19 -> 83.3 | F24: ='7.Rekap Nilai'!F19 -> 75 | G24: ='7.Rekap Nilai'!G19 -> 40 | H24: ='7.Rekap Nilai'!H19 -> 80 | I24: ='7.Rekap Nilai'!I19 -> 85 | J24: =(E24*$K$4+F24*$K$5+IF(D24="OK",G24*$K$7,0)+H24*$K$6+I24*$K$8)/$K$3 -> 76.666667 | K24: =IF(J24>=55,"LULUS ","TIDAK LULUS ") -> LULUS
A25: 9 | B25: ='Master Data'!B29 | C25: ='Master Data'!C29 | D25: ='7.Rekap Nilai'!D20 -> OK | E25: ='7.Rekap Nilai'!E20 -> 75 | F25: ='7.Rekap Nilai'!F20 -> 57 | G25: ='7.Rekap Nilai'!G20 -> 75 | H25: ='7.Rekap Nilai'!H20 -> 80 | I25: ='7.Rekap Nilai'!I20 -> 85 | J25: =(E25*$K$4+F25*$K$5+IF(D25="OK",G25*$K$7,0)+H25*$K$6+I25*$K$8)/$K$3 -> 64.666667 | K25: =IF(J25>=55,"LULUS ","TIDAK LULUS ") -> LULUS
A26: 10 | B26: ='Master Data'!B30 | C26: ='Master Data'!C30 | D26: ='7.Rekap Nilai'!D21 -> OK | E26: ='7.Rekap Nilai'!E21 -> 80 | F26: ='7.Rekap Nilai'!F21 -> 70 | G26: ='7.Rekap Nilai'!G21 -> 58 | H26: ='7.Rekap Nilai'!H21 -> 80 | I26: ='7.Rekap Nilai'!I21 -> 87 | J26: =(E26*$K$4+F26*$K$5+IF(D26="OK",G26*$K$7,0)+H26*$K$6+I26*$K$8)/$K$3 -> 73.333333 | K26: =IF(J26>=55,"LULUS ","TIDAK LULUS ") -> LULUS
A27: 11 | B27: ='Master Data'!B31 | C27: ='Master Data'!C31 | D27: ='7.Rekap Nilai'!D22 -> OK | E27: ='7.Rekap Nilai'!E22 -> 83.3 | F27: ='7.Rekap Nilai'!F22 -> 80 | G27: ='7.Rekap Nilai'!G22 -> 95 | H27: ='7.Rekap Nilai'!H22 -> 80 | I27: ='7.Rekap Nilai'!I22 -> 90 | J27: =(E27*$K$4+F27*$K$5+IF(D27="OK",G27*$K$7,0)+H27*$K$6+I27*$K$8)/$K$3 -> 80 | K27: =IF(J27>=55,"LULUS ","TIDAK LULUS ") -> LULUS
A28: 12 | B28: ='Master Data'!B32 | C28: ='Master Data'!C32 | D28: ='7.Rekap Nilai'!D23 -> OK | E28: ='7.Rekap Nilai'!E23 -> 80 | F28: ='7.Rekap Nilai'!F23 -> 75 | G28: ='7.Rekap Nilai'!G23 -> 30 | H28: ='7.Rekap Nilai'!H23 -> 80 | I28: ='7.Rekap Nilai'!I23 -> 85 | J28: =(E28*$K$4+F28*$K$5+IF(D28="OK",G28*$K$7,0)+H28*$K$6+I28*$K$8)/$K$3 -> 76.666667 | K28: =IF(J28>=55,"LULUS ","TIDAK LULUS ") -> LULUS
... A48: 32 | B48: ='Master Data'!B52 | C48: ='Master Data'!C52 | D48: ='7.Rekap Nilai'!D43 -> OK | E48: ='7.Rekap Nilai'!E43 -> 82.7 | F48: ='7.Rekap Nilai'!F43 -> 80 | G48: ='7.Rekap Nilai'!G43 -> 45 | H48: ='7.Rekap Nilai'!H43 -> 80 | I48: ='7.Rekap Nilai'!I43 -> 90 | J48: =(E48*$K$4+F48*$K$5+IF(D48="OK",G48*$K$7,0)+H48*$K$6+I48*$K$8)/$K$3 -> 80 | K48: =IF(J48>=55,"LULUS ","TIDAK LULUS ") -> LULUS

Sheet 11.CPMK D
A1: ="PEMBOBOTAN NILAI ASESMEN "&'Matriks Asesmen'!E2 -> PEMBOBOTAN NILAI ASESMEN CPMK D
A2: ="Isikan bobot nilai tiap Asesmen "&M1&". Jumlah total bobot nilai dari seluruh asesmen harus sama dengan bobot nilai "&M1 -> Isikan bobot nilai tiap Asesmen . Jumlah total bobot nilai dari seluruh asesmen harus sama dengan bobot nilai
A3: ="Bobot "&'Matriks Asesmen'!E2&" terhadap total jumlah seluruh CPMK:" -> Bobot CPMK D terhadap total jumlah seluruh CPMK: | K3: =SUM(K4:K8) -> 0
A4: Bobot Penilaian-1 | G4: ='Matriks Asesmen'!A4 -> UTS | K4: ='Matriks Asesmen'!E4
A5: Bobot Penilaian-2 | G5: ='Matriks Asesmen'!A5 -> UAS | K5: ='Matriks Asesmen'!E5
A6: Bobot Penilaian-3 | G6: ='Matriks Asesmen'!A6 -> Keaktifan | K6: ='Matriks Asesmen'!E6
A7: Bobot Penilaian-4 | G7: ='Matriks Asesmen'!A7 -> Tugas 1 | K7: ='Matriks Asesmen'!E7
A8: Bobot Penilaian-5 | G8: ='Matriks Asesmen'!A8 -> Tugas 2 | K8: ='Matriks Asesmen'!E8
A9: Bobot Penilaian-6 | G9: ='Matriks Asesmen'!A9 -> Tugas 3 | K9: ='Matriks Asesmen'!E9
A10: Bobot Penilaian-7 | G10: ='Matriks Asesmen'!A10 -> Tugas 4 | K10: ='Matriks Asesmen'!E10
A11: Bobot Penilaian-8 | G11: ='Matriks Asesmen'!A11 -> (bentuk penilaian lainnya) | K11: ='Matriks Asesmen'!E11
A12: Bobot Penilaian-9 | G12: ='Matriks Asesmen'!A12 -> (bentuk penilaian lainnya) | K12: ='Matriks Asesmen'!E12
A13: Bobot Penilaian-10 | G13: ='Matriks Asesmen'!A13 -> (bentuk penilaian lainnya) | K13: ='Matriks Asesmen'!E13
A16: ="ASESMEN CAPAIAN PEMBELAJARAN "&'Matriks Asesmen'!E2 -> ASESMEN CAPAIAN PEMBELAJARAN CPMK D
A17: No | B17: NIM | C17: NAMA | D17: ='7.Rekap Nilai'!D10 -> Jumlah Minimal Presensi | E17: ='7.Rekap Nilai'!E10 -> UTS | F17: ='7.Rekap Nilai'!F10 -> UAS | G17: ='7.Rekap Nilai'!G10 -> Keaktifan | H17: ='7.Rekap Nilai'!H10 -> Tugas 1 | I17: ='7.Rekap Nilai'!I10 -> Tugas 2 | J17: NILAI CAPAIAN | K17: STATUS KELULUSAN CPMK
A18: 1 | B18: ='Master Data'!B21 | C18: ='Master Data'!C21 | D18: ='7.Rekap Nilai'!D12 -> TIDAK BISA UAS | E18: ='7.Rekap Nilai'!E12 -> 48.3 | F18: ='7.Rekap Nilai'!F12 -> 70 | G18: ='7.Rekap Nilai'!G12 -> 40 | H18: ='7.Rekap Nilai'!H12 -> 75 | I18: ='7.Rekap Nilai'!I12 -> 85 | J18: =(E18*$K$4+F18*$K$5+IF(D18="OK",G18*$K$7,0)+H18*$K$6+I18*$K$8)/$K$3 -> #DIV/0! | K18: =IF(J18>=55,"LULUS ","TIDAK LULUS ") -> #DIV/0!
A19: 2 | B19: ='Master Data'!B22 | C19: ='Master Data'!C22 | D19: ='7.Rekap Nilai'!D13 -> OK | E19: ='7.Rekap Nilai'!E13 -> 80 | F19: ='7.Rekap Nilai'!F13 -> 75 | G19: ='7.Rekap Nilai'!G13 -> 55 | H19: ='7.Rekap Nilai'!H13 -> 80 | I19: ='7.Rekap Nilai'!I13 -> 87 | J19: =(E19*$K$4+F19*$K$5+IF(D19="OK",G19*$K$7,0)+H19*$K$6+I19*$K$8)/$K$3 -> #DIV/0! | K19: =IF(J19>=55,"LULUS ","TIDAK LULUS ") -> #DIV/0!
A20: 3 | B20: ='Master Data'!B23 | C20: ='Master Data'!C23 | D20: ='7.Rekap Nilai'!D14 -> OK | E20: ='7.Rekap Nilai'!E14 -> 56.3 | F20: ='7.Rekap Nilai'!F14 -> 46 | G20: ='7.Rekap Nilai'!G14 -> 47 | H20: ='7.Rekap Nilai'!H14 -> 80 | I20: ='7.Rekap Nilai'!I14 -> 85 | J20: =(E20*$K$4+F20*$K$5+IF(D20="OK",G20*$K$7,0)+H20*$K$6+I20*$K$8)/$K$3 -> #DIV/0! | K20: =IF(J20>=55,"LULUS ","TIDAK LULUS ") -> #DIV/0!
A21: 4 | B21: ='Master Data'!B24 | C21: ='Master Data'!C24 | D21: ='7.Rekap Nilai'!D15 -> OK | E21: ='7.Rekap Nilai'!E15 -> 75 | F21: ='7.Rekap Nilai'!F15 -> 75 | G21: ='7.Rekap Nilai'!G15 -> 60 | H21: ='7.Rekap Nilai'!H15 -> 80 | I21: ='7.Rekap Nilai'!I15 -> 85 | J21: =(E21*$K$4+F21*$K$5+IF(D21="OK",G21*$K$7,0)+H21*$K$6+I21*$K$8)/$K$3 -> #DIV/0! | K21: =IF(J21>=55,"LULUS ","TIDAK LULUS ") -> #DIV/0!
A22: 5 | B22: ='Master Data'!B25 | C22: ='Master Data'!C25 | D22: ='7.Rekap Nilai'!D16 -> OK | E22: ='7.Rekap Nilai'!E16 -> 82.6 | F22: ='7.Rekap Nilai'!F16 -> 80 | G22: ='7.Rekap Nilai'!G16 -> 52 | H22: ='7.Rekap Nilai'!H16 -> 80 | I22: ='7.Rekap Nilai'!I16 -> 90 | J22: =(E22*$K$4+F22*$K$5+IF(D22="OK",G22*$K$7,0)+H22*$K$6+I22*$K$8)/$K$3 -> #DIV/0! | K22: =IF(J22>=55,"LULUS ","TIDAK LULUS ") -> #DIV/0!
A23: 6 | B23: ='Master Data'!B26 | C23: ='Master Data'!C26 | D23: ='7.Rekap Nilai'!D17 -> OK | E23: ='7.Rekap Nilai'!E17 -> 75 | F23: ='7.Rekap Nilai'!F17 -> 75 | G23: ='7.Rekap Nilai'!G17 -> 65 | H23: ='7.Rekap Nilai'!H17 -> 80 | I23: ='7.Rekap Nilai'!I17 -> 85 | J23: =(E23*$K$4+F23*$K$5+IF(D23="OK",G23*$K$7,0)+H23*$K$6+I23*$K$8)/$K$3 -> #DIV/0! | K23: =IF(J23>=55,"LULUS ","TIDAK LULUS ") -> #DIV/0!
A24: 7 | B24: ='Master Data'!B27 | C24: ='Master Data'!C27 | D24: ='7.Rekap Nilai'!D18 -> OK | E24: ='7.Rekap Nilai'!E18 -> 56.6 | F24: ='7.Rekap Nilai'!F18 -> 80 | G24: ='7.Rekap Nilai'!G18 -> 55 | H24: ='7.Rekap Nilai'!H18 -> 80 | I24: ='7.Rekap Nilai'!I18 -> 87 | J24: =(E24*$K$4+F24*$K$5+IF(D24="OK",G24*$K$7,0)+H24*$K$6+I24*$K$8)/$K$3 -> #DIV/0! | K24: =IF(J24>=55,"LULUS ","TIDAK LULUS ") -> #DIV/0!
A25: 8 | B25: ='Master Data'!B28 | C25: ='Master Data'!C28 | D25: ='7.Rekap Nilai'!D19 -> OK | E25: ='7.Rekap Nilai'!E19 -> 83.3 | F25: ='7.Rekap Nilai'!F19 -> 75 | G25: ='7.Rekap Nilai'!G19 -> 40 | H25: ='7.Rekap Nilai'!H19 -> 80 | I25: ='7.Rekap Nilai'!I19 -> 85 | J25: =(E25*$K$4+F25*$K$5+IF(D25="OK",G25*$K$7,0)+H25*$K$6+I25*$K$8)/$K$3 -> #DIV/0! | K25: =IF(J25>=55,"LULUS ","TIDAK LULUS ") -> #DIV/0!
A26: 9 | B26: ='Master Data'!B29 | C26: ='Master Data'!C29 | D26: ='7.Rekap Nilai'!D20 -> OK | E26: ='7.Rekap Nilai'!E20 -> 75 | F26: ='7.Rekap Nilai'!F20 -> 57 | G26: ='7.Rekap Nilai'!G20 -> 75 | H26: ='7.Rekap Nilai'!H20 -> 80 | I26: ='7.Rekap Nilai'!I20 -> 85 | J26: =(E26*$K$4+F26*$K$5+IF(D26="OK",G26*$K$7,0)+H26*$K$6+I26*$K$8)/$K$3 -> #DIV/0! | K26: =IF(J26>=55,"LULUS ","TIDAK LULUS ") -> #DIV/0!
A27: 10 | B27: ='Master Data'!B30 | C27: ='Master Data'!C30 | D27: ='7.Rekap Nilai'!D21 -> OK | E27: ='7.Rekap Nilai'!E21 -> 80 | F27: ='7.Rekap Nilai'!F21 -> 70 | G27: ='7.Rekap Nilai'!G21 -> 58 | H27: ='7.Rekap Nilai'!H21 -> 80 | I27: ='7.Rekap Nilai'!I21 -> 87 | J27: =(E27*$K$4+F27*$K$5+IF(D27="OK",G27*$K$7,0)+H27*$K$6+I27*$K$8)/$K$3 -> #DIV/0! | K27: =IF(J27>=55,"LULUS ","TIDAK LULUS ") -> #DIV/0!
A28: 11 | B28: ='Master Data'!B31 | C28: ='Master Data'!C31 | D28: ='7.Rekap Nilai'!D22 -> OK | E28: ='7.Rekap Nilai'!E22 -> 83.3 | F28: ='7.Rekap Nilai'!F22 -> 80 | G28: ='7.Rekap Nilai'!G22 -> 95 | H28: ='7.Rekap Nilai'!H22 -> 80 | I28: ='7.Rekap Nilai'!I22 -> 90 | J28: =(E28*$K$4+F28*$K$5+IF(D28="OK",G28*$K$7,0)+H28*$K$6+I28*$K$8)/$K$3 -> #DIV/0! | K28: =IF(J28>=55,"LULUS ","TIDAK LULUS ") -> #DIV/0!
A29: 12 | B29: ='Master Data'!B32 | C29: ='Master Data'!C32 | D29: ='7.Rekap Nilai'!D23 -> OK | E29: ='7.Rekap Nilai'!E23 -> 80 | F29: ='7.Rekap Nilai'!F23 -> 75 | G29: ='7.Rekap Nilai'!G23 -> 30 | H29: ='7.Rekap Nilai'!H23 -> 80 | I29: ='7.Rekap Nilai'!I23 -> 85 | J29: =(E29*$K$4+F29*$K$5+IF(D29="OK",G29*$K$7,0)+H29*$K$6+I29*$K$8)/$K$3 -> #DIV/0! | K29: =IF(J29>=55,"LULUS ","TIDAK LULUS ") -> #DIV/0!
... A49: 32 | B49: ='Master Data'!B52 | C49: ='Master Data'!C52 | D49: ='7.Rekap Nilai'!D43 -> OK | E49: ='7.Rekap Nilai'!E43 -> 82.7 | F49: ='7.Rekap Nilai'!F43 -> 80 | G49: ='7.Rekap Nilai'!G43 -> 45 | H49: ='7.Rekap Nilai'!H43 -> 80 | I49: ='7.Rekap Nilai'!I43 -> 90 | J49: =(E49*$K$4+F49*$K$5+IF(D49="OK",G49*$K$7,0)+H49*$K$6+I49*$K$8)/$K$3 -> #DIV/0! | K49: =IF(J49>=55,"LULUS ","TIDAK LULUS ") -> #DIV/0!

Sheet 12.CPMK E
A1: ="PEMBOBOTAN NILAI ASESMEN "&'Matriks Asesmen'!F2 -> PEMBOBOTAN NILAI ASESMEN CPMK E
A2: ="Isikan bobot nilai tiap Asesmen "&M1&". Jumlah total bobot nilai dari seluruh asesmen harus sama dengan bobot nilai "&M1 -> Isikan bobot nilai tiap Asesmen . Jumlah total bobot nilai dari seluruh asesmen harus sama dengan bobot nilai
A3: ="Bobot "&'Matriks Asesmen'!F2&" terhadap total jumlah seluruh CPMK:" -> Bobot CPMK E terhadap total jumlah seluruh CPMK: | K3: =SUM(K4:K8) -> 0
A4: Bobot Penilaian-1 | G4: ='Matriks Asesmen'!A4 -> UTS | K4: ='Matriks Asesmen'!F4
A5: Bobot Penilaian-2 | G5: ='Matriks Asesmen'!A5 -> UAS | K5: ='Matriks Asesmen'!F5
A6: Bobot Penilaian-3 | G6: ='Matriks Asesmen'!A6 -> Keaktifan | K6: ='Matriks Asesmen'!F6
A7: Bobot Penilaian-4 | G7: ='Matriks Asesmen'!A7 -> Tugas 1 | K7: ='Matriks Asesmen'!F7
A8: Bobot Penilaian-5 | G8: ='Matriks Asesmen'!A8 -> Tugas 2 | K8: ='Matriks Asesmen'!F8
A9: Bobot Penilaian-6 | G9: ='Matriks Asesmen'!A9 -> Tugas 3 | K9: ='Matriks Asesmen'!F9
A10: Bobot Penilaian-7 | G10: ='Matriks Asesmen'!A10 -> Tugas 4 | K10: ='Matriks Asesmen'!F10
A11: Bobot Penilaian-8 | G11: ='Matriks Asesmen'!A11 -> (bentuk penilaian lainnya) | K11: ='Matriks Asesmen'!F11
A12: Bobot Penilaian-9 | G12: ='Matriks Asesmen'!A12 -> (bentuk penilaian lainnya) | K12: ='Matriks Asesmen'!F12
A13: Bobot Penilaian-10 | G13: ='Matriks Asesmen'!A13 -> (bentuk penilaian lainnya) | K13: ='Matriks Asesmen'!F13
A16: ="ASESMEN CAPAIAN PEMBELAJARAN "&'Matriks Asesmen'!F2 -> ASESMEN CAPAIAN PEMBELAJARAN CPMK E
A17: No | B17: NIM | C17: NAMA | D17: ='7.Rekap Nilai'!D10 -> Jumlah Minimal Presensi | E17: ='7.Rekap Nilai'!E10 -> UTS | F17: ='7.Rekap Nilai'!F10 -> UAS | G17: ='7.Rekap Nilai'!G10 -> Keaktifan | H17: ='7.Rekap Nilai'!H10 -> Tugas 1 | I17: ='7.Rekap Nilai'!I10 -> Tugas 2 | J17: NILAI CAPAIAN | K17: STATUS KELULUSAN CPMK
A18: 1 | B18: ='Master Data'!B21 | C18: ='Master Data'!C21 | D18: ='7.Rekap Nilai'!D12 -> TIDAK BISA UAS | E18: ='7.Rekap Nilai'!E12 -> 48.3 | F18: ='7.Rekap Nilai'!F12 -> 70 | G18: ='7.Rekap Nilai'!G12 -> 40 | H18: ='7.Rekap Nilai'!H12 -> 75 | I18: ='7.Rekap Nilai'!I12 -> 85 | J18: =(E18*$K$4+F18*$K$5+IF(D18="OK",G18*$K$7,0)+H18*$K$6+I18*$K$8)/$K$3 -> #DIV/0! | K18: =IF(J18>=55,"LULUS ","TIDAK LULUS ") -> #DIV/0!
A19: 2 | B19: ='Master Data'!B22 | C19: ='Master Data'!C22 | D19: ='7.Rekap Nilai'!D13 -> OK | E19: ='7.Rekap Nilai'!E13 -> 80 | F19: ='7.Rekap Nilai'!F13 -> 75 | G19: ='7.Rekap Nilai'!G13 -> 55 | H19: ='7.Rekap Nilai'!H13 -> 80 | I19: ='7.Rekap Nilai'!I13 -> 87 | J19: =(E19*$K$4+F19*$K$5+IF(D19="OK",G19*$K$7,0)+H19*$K$6+I19*$K$8)/$K$3 -> #DIV/0! | K19: =IF(J19>=55,"LULUS ","TIDAK LULUS ") -> #DIV/0!
A20: 3 | B20: ='Master Data'!B23 | C20: ='Master Data'!C23 | D20: ='7.Rekap Nilai'!D14 -> OK | E20: ='7.Rekap Nilai'!E14 -> 56.3 | F20: ='7.Rekap Nilai'!F14 -> 46 | G20: ='7.Rekap Nilai'!G14 -> 47 | H20: ='7.Rekap Nilai'!H14 -> 80 | I20: ='7.Rekap Nilai'!I14 -> 85 | J20: =(E20*$K$4+F20*$K$5+IF(D20="OK",G20*$K$7,0)+H20*$K$6+I20*$K$8)/$K$3 -> #DIV/0! | K20: =IF(J20>=55,"LULUS ","TIDAK LULUS ") -> #DIV/0!
A21: 4 | B21: ='Master Data'!B24 | C21: ='Master Data'!C24 | D21: ='7.Rekap Nilai'!D15 -> OK | E21: ='7.Rekap Nilai'!E15 -> 75 | F21: ='7.Rekap Nilai'!F15 -> 75 | G21: ='7.Rekap Nilai'!G15 -> 60 | H21: ='7.Rekap Nilai'!H15 -> 80 | I21: ='7.Rekap Nilai'!I15 -> 85 | J21: =(E21*$K$4+F21*$K$5+IF(D21="OK",G21*$K$7,0)+H21*$K$6+I21*$K$8)/$K$3 -> #DIV/0! | K21: =IF(J21>=55,"LULUS ","TIDAK LULUS ") -> #DIV/0!
A22: 5 | B22: ='Master Data'!B25 | C22: ='Master Data'!C25 | D22: ='7.Rekap Nilai'!D16 -> OK | E22: ='7.Rekap Nilai'!E16 -> 82.6 | F22: ='7.Rekap Nilai'!F16 -> 80 | G22: ='7.Rekap Nilai'!G16 -> 52 | H22: ='7.Rekap Nilai'!H16 -> 80 | I22: ='7.Rekap Nilai'!I16 -> 90 | J22: =(E22*$K$4+F22*$K$5+IF(D22="OK",G22*$K$7,0)+H22*$K$6+I22*$K$8)/$K$3 -> #DIV/0! | K22: =IF(J22>=55,"LULUS ","TIDAK LULUS ") -> #DIV/0!
A23: 6 | B23: ='Master Data'!B26 | C23: ='Master Data'!C26 | D23: ='7.Rekap Nilai'!D17 -> OK | E23: ='7.Rekap Nilai'!E17 -> 75 | F23: ='7.Rekap Nilai'!F17 -> 75 | G23: ='7.Rekap Nilai'!G17 -> 65 | H23: ='7.Rekap Nilai'!H17 -> 80 | I23: ='7.Rekap Nilai'!I17 -> 85 | J23: =(E23*$K$4+F23*$K$5+IF(D23="OK",G23*$K$7,0)+H23*$K$6+I23*$K$8)/$K$3 -> #DIV/0! | K23: =IF(J23>=55,"LULUS ","TIDAK LULUS ") -> #DIV/0!
A24: 7 | B24: ='Master Data'!B27 | C24: ='Master Data'!C27 | D24: ='7.Rekap Nilai'!D18 -> OK | E24: ='7.Rekap Nilai'!E18 -> 56.6 | F24: ='7.Rekap Nilai'!F18 -> 80 | G24: ='7.Rekap Nilai'!G18 -> 55 | H24: ='7.Rekap Nilai'!H18 -> 80 | I24: ='7.Rekap Nilai'!I18 -> 87 | J24: =(E24*$K$4+F24*$K$5+IF(D24="OK",G24*$K$7,0)+H24*$K$6+I24*$K$8)/$K$3 -> #DIV/0! | K24: =IF(J24>=55,"LULUS ","TIDAK LULUS ") -> #DIV/0!
A25: 8 | B25: ='Master Data'!B28 | C25: ='Master Data'!C28 | D25: ='7.Rekap Nilai'!D19 -> OK | E25: ='7.Rekap Nilai'!E19 -> 83.3 | F25: ='7.Rekap Nilai'!F19 -> 75 | G25: ='7.Rekap Nilai'!G19 -> 40 | H25: ='7.Rekap Nilai'!H19 -> 80 | I25: ='7.Rekap Nilai'!I19 -> 85 | J25: =(E25*$K$4+F25*$K$5+IF(D25="OK",G25*$K$7,0)+H25*$K$6+I25*$K$8)/$K$3 -> #DIV/0! | K25: =IF(J25>=55,"LULUS ","TIDAK LULUS ") -> #DIV/0!
A26: 9 | B26: ='Master Data'!B29 | C26: ='Master Data'!C29 | D26: ='7.Rekap Nilai'!D20 -> OK | E26: ='7.Rekap Nilai'!E20 -> 75 | F26: ='7.Rekap Nilai'!F20 -> 57 | G26: ='7.Rekap Nilai'!G20 -> 75 | H26: ='7.Rekap Nilai'!H20 -> 80 | I26: ='7.Rekap Nilai'!I20 -> 85 | J26: =(E26*$K$4+F26*$K$5+IF(D26="OK",G26*$K$7,0)+H26*$K$6+I26*$K$8)/$K$3 -> #DIV/0! | K26: =IF(J26>=55,"LULUS ","TIDAK LULUS ") -> #DIV/0!
A27: 10 | B27: ='Master Data'!B30 | C27: ='Master Data'!C30 | D27: ='7.Rekap Nilai'!D21 -> OK | E27: ='7.Rekap Nilai'!E21 -> 80 | F27: ='7.Rekap Nilai'!F21 -> 70 | G27: ='7.Rekap Nilai'!G21 -> 58 | H27: ='7.Rekap Nilai'!H21 -> 80 | I27: ='7.Rekap Nilai'!I21 -> 87 | J27: =(E27*$K$4+F27*$K$5+IF(D27="OK",G27*$K$7,0)+H27*$K$6+I27*$K$8)/$K$3 -> #DIV/0! | K27: =IF(J27>=55,"LULUS ","TIDAK LULUS ") -> #DIV/0!
A28: 11 | B28: ='Master Data'!B31 | C28: ='Master Data'!C31 | D28: ='7.Rekap Nilai'!D22 -> OK | E28: ='7.Rekap Nilai'!E22 -> 83.3 | F28: ='7.Rekap Nilai'!F22 -> 80 | G28: ='7.Rekap Nilai'!G22 -> 95 | H28: ='7.Rekap Nilai'!H22 -> 80 | I28: ='7.Rekap Nilai'!I22 -> 90 | J28: =(E28*$K$4+F28*$K$5+IF(D28="OK",G28*$K$7,0)+H28*$K$6+I28*$K$8)/$K$3 -> #DIV/0! | K28: =IF(J28>=55,"LULUS ","TIDAK LULUS ") -> #DIV/0!
A29: 12 | B29: ='Master Data'!B32 | C29: ='Master Data'!C32 | D29: ='7.Rekap Nilai'!D23 -> OK | E29: ='7.Rekap Nilai'!E23 -> 80 | F29: ='7.Rekap Nilai'!F23 -> 75 | G29: ='7.Rekap Nilai'!G23 -> 30 | H29: ='7.Rekap Nilai'!H23 -> 80 | I29: ='7.Rekap Nilai'!I23 -> 85 | J29: =(E29*$K$4+F29*$K$5+IF(D29="OK",G29*$K$7,0)+H29*$K$6+I29*$K$8)/$K$3 -> #DIV/0! | K29: =IF(J29>=55,"LULUS ","TIDAK LULUS ") -> #DIV/0!
... A49: 32 | B49: ='Master Data'!B52 | C49: ='Master Data'!C52 | D49: ='7.Rekap Nilai'!D43 -> OK | E49: ='7.Rekap Nilai'!E43 -> 82.7 | F49: ='7.Rekap Nilai'!F43 -> 80 | G49: ='7.Rekap Nilai'!G43 -> 45 | H49: ='7.Rekap Nilai'!H43 -> 80 | I49: ='7.Rekap Nilai'!I43 -> 90 | J49: =(E49*$K$4+F49*$K$5+IF(D49="OK",G49*$K$7,0)+H49*$K$6+I49*$K$8)/$K$3 -> #DIV/0! | K49: =IF(J49>=55,"LULUS ","TIDAK LULUS ") -> #DIV/0!

Sheet 13. Laporan OBE
A1: UNIVERSITAS MARITIM RAJA ALI HAJI | P1: ASSESMENT CPMK | Q1: SANGAT BAIK | R1: BAIK | S1: CUKUP | T1: KURANG | U1: TIDAK LULUS CPMK | V1: TOTAL | W1: PERSENTASE KELULUSAN
A2: ='Master Data'!C15 -> Fakultas …
